Workbook

Sheet DictionaryName
A1: Start | B1: Dictionary ID | C1: DictionaryFile | D1: DictionaryName | E1: Description
E2: Leave this line blank
B3: loadTestReferenceSystem | C3: loadTestReferenceSystem | D3: DIGGS Load Test Reference System Codelist Definitions | E3: Codes classifying how movement was referenced during a load test. Used for the value of diggs:AbstractLoadTestProcedureType/referenceSystem (StaticLoadTest, RapidLoadTest and DynamicLoadTest). Both ASTM D1143/D1143M and EN ISO 22477-1 require the reference system to be independent of the reaction system and unaffected by ground movement caused by the test; this dictionary records which arrangement was used, not that it satisfied the requirement.

Sheet Definitions
A1: Start | B1: ID | C1: Name | D1: Description | E1: DataType | F1: QuantityClass | G1: Authority | H1: Reference
A2: =IF(ISNA(VLOOKUP(B2,AssociatedElements!B$2:B$999,1,FALSE)),"Not used","") | B2: independent_reference_beam | C2: Independent Reference Beam | D2: Displacement measured against a fixed reference beam supported clear of the reaction system and of any ground disturbed by the test. | E2: string | G2: DIGGS
A3: =IF(ISNA(VLOOKUP(B3,AssociatedElements!B$2:B$999,1,FALSE)),"Not used","") | B3: optical_survey | C3: Optical Survey | D3: Displacement measured by optical or total-station survey referenced to a fixed benchmark independent of the reaction system. | E3: string | G3: DIGGS
A4: =IF(ISNA(VLOOKUP(B4,AssociatedElements!B$2:B$999,1,FALSE)),"Not used","") | B4: satellite_positioning | C4: Satellite Positioning | D4: Displacement measured by real-time GNSS/satellite positioning referenced to a fixed benchmark. | E4: string | G4: DIGGS
A5: =IF(ISNA(VLOOKUP(B5,AssociatedElements!B$2:B$999,1,FALSE)),"Not used","") | B5: other | C5: Other | D5: A reference system other than an independent reference beam, optical survey, or satellite positioning. | E5: string | G5: DIGGS
A6: =IF(ISNA(VLOOKUP(B6,AssociatedElements!B$2:B2944,1,FALSE)),"Not used","")
A7: =IF(ISNA(VLOOKUP(B7,AssociatedElements!B$2:B2945,1,FALSE)),"Not used","")
A8: =IF(ISNA(VLOOKUP(B8,AssociatedElements!B$2:B2946,1,FALSE)),"Not used","")
A9: =IF(ISNA(VLOOKUP(B9,AssociatedElements!B$2:B2947,1,FALSE)),"Not used","")
A10: =IF(ISNA(VLOOKUP(B10,AssociatedElements!B$2:B2948,1,FALSE)),"Not used","")
A11: =IF(ISNA(VLOOKUP(B11,AssociatedElements!B$2:B2949,1,FALSE)),"Not used","")
A12: =IF(ISNA(VLOOKUP(B12,AssociatedElements!B$2:B2950,1,FALSE)),"Not used","")
A13: =IF(ISNA(VLOOKUP(B13,AssociatedElements!B$2:B2951,1,FALSE)),"Not used","")
A14: =IF(ISNA(VLOOKUP(B14,AssociatedElements!B$2:B2952,1,FALSE)),"Not used","")
A15: =IF(ISNA(VLOOKUP(B15,AssociatedElements!B$2:B2953,1,FALSE)),"Not used","")
A16: =IF(ISNA(VLOOKUP(B16,AssociatedElements!B$2:B2954,1,FALSE)),"Not used","")
A17: =IF(ISNA(VLOOKUP(B17,AssociatedElements!B$2:B2955,1,FALSE)),"Not used","")
... A37: =IF(ISNA(VLOOKUP(B37,AssociatedElements!B$2:B2975,1,FALSE)),"Not used","")

Sheet AssociatedElements
A1: Start | B1: ID | C1: SourceElement | D1: ConditionalElement
A2: =IF(ISNA(VLOOKUP(B2,Definitions!B$2:B$999,1,FALSE)),"Not listed","") | B2: independent_reference_beam | C2: //diggs:StaticLoadTest/diggs:referenceSystem
A3: =IF(ISNA(VLOOKUP(B3,Definitions!B$2:B$999,1,FALSE)),"Not listed","") | B3: independent_reference_beam | C3: //diggs:RapidLoadTest/diggs:referenceSystem
A4: =IF(ISNA(VLOOKUP(B4,Definitions!B$2:B$999,1,FALSE)),"Not listed","") | B4: independent_reference_beam | C4: //diggs:DynamicLoadTest/diggs:referenceSystem
A5: =IF(ISNA(VLOOKUP(B5,Definitions!B$2:B$999,1,FALSE)),"Not listed","") | B5: optical_survey | C5: //diggs:StaticLoadTest/diggs:referenceSystem
A6: =IF(ISNA(VLOOKUP(B6,Definitions!B$2:B$999,1,FALSE)),"Not listed","") | B6: optical_survey | C6: //diggs:RapidLoadTest/diggs:referenceSystem
A7: =IF(ISNA(VLOOKUP(B7,Definitions!B$2:B$999,1,FALSE)),"Not listed","") | B7: optical_survey | C7: //diggs:DynamicLoadTest/diggs:referenceSystem
A8: =IF(ISNA(VLOOKUP(B8,Definitions!B$2:B$999,1,FALSE)),"Not listed","") | B8: satellite_positioning | C8: //diggs:StaticLoadTest/diggs:referenceSystem
A9: =IF(ISNA(VLOOKUP(B9,Definitions!B$2:B$999,1,FALSE)),"Not listed","") | B9: satellite_positioning | C9: //diggs:RapidLoadTest/diggs:referenceSystem
A10: =IF(ISNA(VLOOKUP(B10,Definitions!B$2:B$999,1,FALSE)),"Not listed","") | B10: satellite_positioning | C10: //diggs:DynamicLoadTest/diggs:referenceSystem
A11: =IF(ISNA(VLOOKUP(B11,Definitions!B$2:B$999,1,FALSE)),"Not listed","") | B11: other | C11: //diggs:StaticLoadTest/diggs:referenceSystem
A12: =IF(ISNA(VLOOKUP(B12,Definitions!B$2:B$999,1,FALSE)),"Not listed","") | B12: other | C12: //diggs:RapidLoadTest/diggs:referenceSystem
A13: =IF(ISNA(VLOOKUP(B13,Definitions!B$2:B$999,1,FALSE)),"Not listed","") | B13: other | C13: //diggs:DynamicLoadTest/diggs:referenceSystem
A14: =IF(ISNA(VLOOKUP(B14,Definitions!B$2:B$1839,1,FALSE)),"Not listed","") | B14: independent_reference_beam | C14: //diggs:LateralLoadTest/diggs:referenceSystem
A15: =IF(ISNA(VLOOKUP(B15,Definitions!B$2:B$1839,1,FALSE)),"Not listed","") | B15: independent_reference_beam | C15: //diggs:PlateLoadTest/diggs:referenceSystem
A16: =IF(ISNA(VLOOKUP(B16,Definitions!B$2:B$1839,1,FALSE)),"Not listed","") | B16: independent_reference_beam | C16: //diggs:ZoneLoadTest/diggs:referenceSystem
A17: =IF(ISNA(VLOOKUP(B17,Definitions!B$2:B$1839,1,FALSE)),"Not listed","") | B17: optical_survey | C17: //diggs:LateralLoadTest/diggs:referenceSystem
A18: =IF(ISNA(VLOOKUP(B18,Definitions!B$2:B$1839,1,FALSE)),"Not listed","") | B18: optical_survey | C18: //diggs:PlateLoadTest/diggs:referenceSystem
A19: =IF(ISNA(VLOOKUP(B19,Definitions!B$2:B$1839,1,FALSE)),"Not listed","") | B19: optical_survey | C19: //diggs:ZoneLoadTest/diggs:referenceSystem
A20: =IF(ISNA(VLOOKUP(B20,Definitions!B$2:B$1839,1,FALSE)),"Not listed","") | B20: satellite_positioning | C20: //diggs:LateralLoadTest/diggs:referenceSystem
A21: =IF(ISNA(VLOOKUP(B21,Definitions!B$2:B$1839,1,FALSE)),"Not listed","") | B21: satellite_positioning | C21: //diggs:PlateLoadTest/diggs:referenceSystem
A22: =IF(ISNA(VLOOKUP(B22,Definitions!B$2:B$1839,1,FALSE)),"Not listed","") | B22: satellite_positioning | C22: //diggs:ZoneLoadTest/diggs:referenceSystem
A23: =IF(ISNA(VLOOKUP(B23,Definitions!B$2:B$1839,1,FALSE)),"Not listed","") | B23: other | C23: //diggs:LateralLoadTest/diggs:referenceSystem
A24: =IF(ISNA(VLOOKUP(B24,Definitions!B$2:B$1839,1,FALSE)),"Not listed","") | B24: other | C24: //diggs:PlateLoadTest/diggs:referenceSystem
A25: =IF(ISNA(VLOOKUP(B25,Definitions!B$2:B$1839,1,FALSE)),"Not listed","") | B25: other | C25: //diggs:ZoneLoadTest/diggs:referenceSystem
A26: =IF(ISNA(VLOOKUP(B26,Definitions!B$2:B$1839,1,FALSE)),"Not listed","")
A27: =IF(ISNA(VLOOKUP(B27,Definitions!B$2:B$1839,1,FALSE)),"Not listed","")
A28: =IF(ISNA(VLOOKUP(B28,Definitions!B$2:B$1839,1,FALSE)),"Not listed","")
A29: =IF(ISNA(VLOOKUP(B29,Definitions!B$2:B$1839,1,FALSE)),"Not listed","")
A30: =IF(ISNA(VLOOKUP(B30,Definitions!B$2:B$1839,1,FALSE)),"Not listed","")
A31: =IF(ISNA(VLOOKUP(B31,Definitions!B$2:B$1839,1,FALSE)),"Not listed","")
A32: =IF(ISNA(VLOOKUP(B32,Definitions!B$2:B$1839,1,FALSE)),"Not listed","")
A33: =IF(ISNA(VLOOKUP(B33,Definitions!B$2:B$1839,1,FALSE)),"Not listed","")
A34: =IF(ISNA(VLOOKUP(B34,Definitions!B$2:B$1839,1,FALSE)),"Not listed","")
A35: =IF(ISNA(VLOOKUP(B35,Definitions!B$2:B$1839,1,FALSE)),"Not listed","")
A36: =IF(ISNA(VLOOKUP(B36,Definitions!B$2:B$1839,1,FALSE)),"Not listed","")
A37: =IF(ISNA(VLOOKUP(B37,Definitions!B$2:B$1839,1,FALSE)),"Not listed","")

Sheet AlternateNames
A1: Start | B1: ID | C1: Name | D1: codeSpace
A2: =IF(ISNA(VLOOKUP(B2,Definitions!B$2:B$1839,1,FALSE)),"Not listed","") | B2: LFS | C2: An alternate name for the definition code given in ID | D2: A URI to provide context for the name. Typically this might identify an authority, a language. a dictionary, or some other metadata value

Sheet Lists
A1: DataType | B1: DataType2 | C1: QuantityClass | D1: Column2 | E1: Column3
B2: anyURI | C2: absorbed dose
B3: base64binary | C3: activity [of radioactivity]
B4: boolean | C4: amount of substance
B5: byte | C5: amount of substance per amount of substance
B6: date | C6: amount of substance per area
B7: dateTime | C7: amount of substance per mass | D7: use for cation exchange capacity | E7: not yet used nor in EML Dictionary
B8: decimal | C8: amount of substance per time
B9: double | C9: (amount of substance per time) per area
B10: duration | C10: amount of substance per volume
B11: float | C11: angle per length
B12: gDay | C12: angle per volume
B13: gMonth | C13: angular acceleration
B14: gMonthDay | C14: angular velocity
B15: gYear | C15: api gamma ray
B16: gYearMonth | C16: api gravity
B17: hexBinary | C17: api neutron
B18: integer | C18: area
B19: language | C19: area per amount of substance
B20: long | C20: area per area
B21: negativeInteger | C21: area per count | D21: In EML schema but not in EML dictionary
B22: nonNegativeInteger | C22: area per mass
B23: nonPositiveInteger | C23: area per time
B24: normalizedString | C24: area per volume
B25: positiveInteger | C25: attenuation per frequency interval
B26: short | C26: capacitance
B27: string | C27: data transfer speed
B28: string | C28: diffusion coefficient
B29: time | C29: diffusive time of flight | D29: In EML schema but not in EML dictionary
B30: token | C30: digital storage
B31: unsignedByte | C31: dimensionless
B32: unsignedInt | C32: dipole moment
B33: unsignedLong | C33: dose equivalent
B34: unsignedShort | C34: dynamic viscosity
B35: vector | C35: electric charge
C36: electric charge per area
C37: electric charge per mass
C38: electric charge per volume
C39: electric conductance
C40: electric conductivity
...
