Workbook

Sheet DictionaryName
A1: Start | B1: Dictionary ID | C1: DictionaryFile | D1: DictionaryName | E1: Description
E2: Leave this line blank
B3: equipmentClass | C3: equipmentClass | D3: DIGGS Equipment Class Codelist Definitions | E3: Codes that identify what a piece of equipment is. These codes are used for the value of the class property of the generic Equipment and Sensor objects. Where class appears on a specialized equipment feature such as DrillRig or GroutPump it subdivides that feature's own kind rather than naming it, and takes its values from a codelist specific to that feature, not from this one.

Sheet Definitions
A1: Start | B1: ID | C1: Name | D1: Description | E1: DataType | F1: QuantityClass | G1: Authority | H1: Reference
A2: =IF(ISNA(VLOOKUP(B2,AssociatedElements!B$2:B2940,1,FALSE)),"Not used","") | B2: piezometer | C2: Piezometer | D2: An instrument that measures pore water pressure, and hence groundwater head, at a point in the ground. Deliberately coarse: the vibrating-wire, pneumatic, standpipe and push-in variants differ in how the pressure is transduced rather than in what is measured, and are better distinguished by the make and modelNumber properties the equipment object already carries than by separate codes here.
A3: =IF(ISNA(VLOOKUP(B3,AssociatedElements!B$2:B2941,1,FALSE)),"Not used","") | B3: inclinometer | C3: Inclinometer | D3: An instrument that measures the deviation of a cased borehole from vertical, read as a profile down the casing, so that lateral ground movement is obtained as a displacement against depth over time.
A4: =IF(ISNA(VLOOKUP(B4,AssociatedElements!B$2:B2942,1,FALSE)),"Not used","") | B4: extensometer | C4: Extensometer | D4: An instrument that measures change in distance between two or more anchored points, most commonly along a borehole axis, giving compression or extension of the ground between them.
A5: =IF(ISNA(VLOOKUP(B5,AssociatedElements!B$2:B2943,1,FALSE)),"Not used","") | B5: settlement_cell | C5: Settlement cell | D5: A liquid-level or pressure-based instrument that measures vertical settlement at a point remotely, without requiring a surveyor to occupy the point. Distinct from a settlement plate, which is passive hardware read by optical survey and is therefore not a sensor.
A6: =IF(ISNA(VLOOKUP(B6,AssociatedElements!B$2:B2944,1,FALSE)),"Not used","") | B6: earth_pressure_cell | C6: Earth pressure cell | D6: An instrument that measures total stress in the ground or at an interface such as a structure face or a column head. The instrument central to verifying load transfer in a rigid inclusion platform, where the design predicts distinct stresses on the element head and on the soil between heads.
A7: =IF(ISNA(VLOOKUP(B7,AssociatedElements!B$2:B2945,1,FALSE)),"Not used","") | B7: strain_gauge | C7: Strain gauge | D7: An instrument that measures strain in a structural element, from which stress and load are inferred given the element's stiffness and section.
A8: =IF(ISNA(VLOOKUP(B8,AssociatedElements!B$2:B2946,1,FALSE)),"Not used","") | B8: load_cell | C8: Load cell | D8: An instrument that measures an applied force directly, used at the head of a tested element, in an anchor or strut, or in a load-test reaction frame.
A9: =IF(ISNA(VLOOKUP(B9,AssociatedElements!B$2:B2947,1,FALSE)),"Not used","") | B9: tiltmeter | C9: Tiltmeter | D9: An instrument that measures rotation of a structure or of the ground surface about a horizontal axis.
A10: =IF(ISNA(VLOOKUP(B10,AssociatedElements!B$2:B2948,1,FALSE)),"Not used","") | B10: crackmeter | C10: Crackmeter | D10: An instrument that measures change in the width of a joint or crack in a structure, used to monitor whether observed distress is progressing.
A11: =IF(ISNA(VLOOKUP(B11,AssociatedElements!B$2:B2949,1,FALSE)),"Not used","") | B11: thermistor | C11: Thermistor | D11: A temperature-sensing element, deployed on its own for ground thermal monitoring and embedded in most vibrating-wire instruments for the temperature correction their readings require.
A12: =IF(ISNA(VLOOKUP(B12,AssociatedElements!B$2:B2950,1,FALSE)),"Not used","") | B12: accelerometer | C12: Accelerometer | D12: An instrument that measures acceleration, used for construction vibration monitoring and for dynamic testing of deep foundation elements.
A13: =IF(ISNA(VLOOKUP(B13,AssociatedElements!B$2:B2951,1,FALSE)),"Not used","") | B13: settlement_plate | C13: Settlement plate | D13: A plate with a riser installed at a known level and read by optical survey, giving settlement at a point. Passive hardware rather than a sensor: it transduces nothing and produces a reading only when a surveyor occupies it, which is why it is an Equipment and not a Sensor.
... A27: =IF(ISNA(VLOOKUP(B27,AssociatedElements!B$2:B2965,1,FALSE)),"Not used","") | B27: concrete_pump | C27: Concrete pump | D27: A pump delivering ready-mixed concrete to the tool during column formation, typical of controlled-modulus-column practice.
A28: =IF(ISNA(VLOOKUP(B28,AssociatedElements!B$2:B2966,1,FALSE)),"Not used","") | B28: rapid_load_device | C28: Rapid Load Test Device | D28: The pneumatic or hydraulic force-pulse generator used to apply the load in a rapid load test - a Statnamic device or an equivalent force-pulse actuator, per ASTM D7383 or EN ISO 22477-10. | E28: string | G28: DIGGS
A29: =IF(ISNA(VLOOKUP(B29,AssociatedElements!B$2:B2967,1,FALSE)),"Not used","") | B29: dynamic_test_hammer | C29: Dynamic Load Test Hammer | D29: The impact hammer used to apply the blow(s) in a high-strain dynamic load test, per ASTM D4945 or EN ISO 22477-4. | E29: string | G29: DIGGS
A30: =IF(ISNA(VLOOKUP(B30,AssociatedElements!B$2:B2968,1,FALSE)),"Not used","") | B30: low_strain_impact_hammer | C30: Low-Strain Impact Hammer | D30: The small handheld hammer (typically plastic- or rubber-tipped) used to apply the impact in a low-strain integrity test, per ASTM D5882 or NF P94-160-2/-4. Distinct from equipmentClass.xml#dynamic_test_hammer, the much larger drop or diesel hammer used to apply a high-strain blow in ASTM D4945 dynamic load testing - the two tests use different equipment at entirely different energy scales. | E30: string | G30: DIGGS
A31: =IF(ISNA(VLOOKUP(B31,AssociatedElements!B$2:B$999,1,FALSE)),"Not used","") | B31: thermal_integrity_probe | C31: Thermal Integrity Profiling Probe | D31: The probe lowered into access ducts to take temperature readings in ASTM D7949 Method A thermal integrity profiling. Distinct from equipmentClass.xml#thermistor, which is the embedded sensor Method B uses instead - the two methods use different equipment classes for the same underlying measurement. | E31: string | G31: DIGGS
A32: =IF(ISNA(VLOOKUP(B32,AssociatedElements!B$2:B$999,1,FALSE)),"Not used","") | B32: embedded_fiber_optic_cable | C32: Embedded Fiber-Optic Cable | D32: The fiber-optic cable attached to the reinforcing cage and cast into the concrete for ASTM D7949 Method C thermal integrity profiling, giving effectively continuous temperature coverage along the element's length. | E32: string | G32: DIGGS
A33: =IF(ISNA(VLOOKUP(B33,AssociatedElements!B$2:B2971,1,FALSE)),"Not used","")
A34: =IF(ISNA(VLOOKUP(B34,AssociatedElements!B$2:B2972,1,FALSE)),"Not used","")
A35: =IF(ISNA(VLOOKUP(B35,AssociatedElements!B$2:B2973,1,FALSE)),"Not used","")
A36: =IF(ISNA(VLOOKUP(B36,AssociatedElements!B$2:B2974,1,FALSE)),"Not used","")
A37: =IF(ISNA(VLOOKUP(B37,AssociatedElements!B$2:B2975,1,FALSE)),"Not used","")

Sheet AssociatedElements
A1: Start | B1: ID | C1: SourceElement | D1: ConditionalElement
A2: =IF(ISNA(VLOOKUP(#REF!,Definitions!B$2:B$1839,1,FALSE)),"Not listed","") | B2: piezometer | C2: //diggs:Sensor/diggs:class
A3: =IF(ISNA(VLOOKUP(B3,Definitions!B$2:B$1839,1,FALSE)),"Not listed","") | B3: inclinometer | C3: //diggs:Sensor/diggs:class
A4: =IF(ISNA(VLOOKUP(B4,Definitions!B$2:B$1839,1,FALSE)),"Not listed","") | B4: extensometer | C4: //diggs:Sensor/diggs:class
A5: =IF(ISNA(VLOOKUP(B5,Definitions!B$2:B$1839,1,FALSE)),"Not listed","") | B5: settlement_cell | C5: //diggs:Sensor/diggs:class
A6: =IF(ISNA(VLOOKUP(B6,Definitions!B$2:B$1839,1,FALSE)),"Not listed","") | B6: earth_pressure_cell | C6: //diggs:Sensor/diggs:class
A7: =IF(ISNA(VLOOKUP(B7,Definitions!B$2:B$1839,1,FALSE)),"Not listed","") | B7: strain_gauge | C7: //diggs:Sensor/diggs:class
A8: =IF(ISNA(VLOOKUP(B8,Definitions!B$2:B$1839,1,FALSE)),"Not listed","") | B8: load_cell | C8: //diggs:Sensor/diggs:class
A9: =IF(ISNA(VLOOKUP(B9,Definitions!B$2:B$1839,1,FALSE)),"Not listed","") | B9: tiltmeter | C9: //diggs:Sensor/diggs:class
A10: =IF(ISNA(VLOOKUP(B10,Definitions!B$2:B$1839,1,FALSE)),"Not listed","") | B10: crackmeter | C10: //diggs:Sensor/diggs:class
A11: =IF(ISNA(VLOOKUP(B11,Definitions!B$2:B$1839,1,FALSE)),"Not listed","") | B11: thermistor | C11: //diggs:Sensor/diggs:class
A12: =IF(ISNA(VLOOKUP(B12,Definitions!B$2:B$1839,1,FALSE)),"Not listed","") | B12: accelerometer | C12: //diggs:Sensor/diggs:class
A13: =IF(ISNA(VLOOKUP(B13,Definitions!B$2:B$1839,1,FALSE)),"Not listed","") | B13: settlement_plate | C13: //diggs:Equipment/diggs:class
A14: =IF(ISNA(VLOOKUP(B14,Definitions!B$2:B$1839,1,FALSE)),"Not listed","") | B14: survey_monument | C14: //diggs:Equipment/diggs:class
... A30: =IF(ISNA(VLOOKUP(B30,Definitions!B$2:B$1839,1,FALSE)),"Not listed","") | B30: low_strain_impact_hammer | C30: //diggs:Equipment/diggs:class
A31: =IF(ISNA(VLOOKUP(B31,Definitions!B$2:B$999,1,FALSE)),"Not listed","") | B31: thermal_integrity_probe | C31: //diggs:Equipment/diggs:class
A32: =IF(ISNA(VLOOKUP(B32,Definitions!B$2:B$999,1,FALSE)),"Not listed","") | B32: embedded_fiber_optic_cable | C32: //diggs:Equipment/diggs:class
A33: =IF(ISNA(VLOOKUP(B33,Definitions!B$2:B$1839,1,FALSE)),"Not listed","")
A34: =IF(ISNA(VLOOKUP(B34,Definitions!B$2:B$1839,1,FALSE)),"Not listed","")
A35: =IF(ISNA(VLOOKUP(B35,Definitions!B$2:B$1839,1,FALSE)),"Not listed","")
A36: =IF(ISNA(VLOOKUP(B36,Definitions!B$2:B$1839,1,FALSE)),"Not listed","")
A37: =IF(ISNA(VLOOKUP(B37,Definitions!B$2:B$1839,1,FALSE)),"Not listed","")

Sheet AlternateNames
A1: Start | B1: ID | C1: Name | D1: codeSpace
A2: =IF(ISNA(VLOOKUP(B2,Definitions!B$2:B$1839,1,FALSE)),"Not listed","")

Sheet Lists
A1: DataType | B1: DataType2 | C1: QuantityClass | D1: Column2 | E1: Column3
B2: anyURI | C2: absorbed dose
B3: base64binary | C3: activity [of radioactivity]
B4: boolean | C4: amount of substance
B5: byte | C5: amount of substance per amount of substance
B6: date | C6: amount of substance per area
B7: dateTime | C7: amount of substance per mass | D7: use for cation exchange capacity | E7: not yet used nor in EML Dictionary
B8: decimal | C8: amount of substance per time
B9: double | C9: (amount of substance per time) per area
B10: duration | C10: amount of substance per volume
B11: float | C11: angle per length
B12: gDay | C12: angle per volume
B13: gMonth | C13: angular acceleration
B14: gMonthDay | C14: angular velocity
B15: gYear | C15: api gamma ray
B16: gYearMonth | C16: api gravity
B17: hexBinary | C17: api neutron
B18: integer | C18: area
B19: language | C19: area per amount of substance
B20: long | C20: area per area
B21: negativeInteger | C21: area per count | D21: In EML schema but not in EML dictionary
B22: nonNegativeInteger | C22: area per mass
B23: nonPositiveInteger | C23: area per time
B24: normalizedString | C24: area per volume
B25: positiveInteger | C25: attenuation per frequency interval
B26: short | C26: capacitance
B27: string | C27: data transfer speed
B28: string | C28: diffusion coefficient
B29: time | C29: diffusive time of flight | D29: In EML schema but not in EML dictionary
B30: token | C30: digital storage
B31: unsignedByte | C31: dimensionless
B32: unsignedInt | C32: dipole moment
B33: unsignedLong | C33: dose equivalent
B34: unsignedShort | C34: dynamic viscosity
B35: vector | C35: electric charge
C36: electric charge per area
C37: electric charge per mass
C38: electric charge per volume
C39: electric conductance
C40: electric conductivity
...
