Workbook

Sheet DictionaryName
A1: Start | B1: Dictionary ID | C1: DictionaryFile | D1: DictionaryName | E1: Description
E2: Leave this line blank
B3: propertyClass | C3: gp_properties | D3: DIGGS Measurement Properties for Geophysics | E3: This dictionary contains the values for the propertyClass property of the diggs:Property object and the measurand property of the diggs:Detector object when used within the Test feature, where thetesting procedure is a ProcessedGeophysicalsurvey or WirelineLog. These values serve to define the ultimate results of geophysical field measurements. The Xpaths to these occurrences are: 1) //diggs:Property/diggs:propertyClass.

Sheet Definitions
A1: Start | B1: ID | C1: Name | D1: Description | E1: DataType | F1: QuantityClass | G1: Authority | H1: Reference
A2: =IF(ISNA(VLOOKUP(B2,AssociatedElements!B$2:B2954,1,FALSE)),"Not used","") | B2: gamma_ray | C2: Gamma Ray | D2: The intensity of natural gamma-ray radiation emitted from formations containing radioactive elements, such as Potassium, Thorium, and Uranium. Measured according to API specifications or as counts per time | E2: double | F2: API gamma ray
A3: =IF(ISNA(VLOOKUP(B3,AssociatedElements!B$2:B2947,1,FALSE)),"Not used","") | B3: dielectric_constant | C3: Dielectric Constant | D3: The ratio of the permittivity of the medium to the permittivity of the free space | E3: double
A4: =IF(ISNA(VLOOKUP(B4,AssociatedElements!B$2:B2958,1,FALSE)),"Not used","") | B4: in_phase_x | C4: X Component of In Phase | D4: the x component of the in-phase wave component. | E4: double
A5: =IF(ISNA(VLOOKUP(B5,AssociatedElements!B$2:B2959,1,FALSE)),"Not used","") | B5: in_phase_y | C5: Y Component of In Phase | D5: the y component of the in-phase wave component. | E5: double
A6: =IF(ISNA(VLOOKUP(B6,AssociatedElements!B$2:B2967,1,FALSE)),"Not used","") | B6: magnetic_susceptibility | C6: Magnetic Susceptibility | D6: The degree to which a material becomes magnetized in response to an applied magnetic field. | E6: double
A7: =IF(ISNA(VLOOKUP(B7,AssociatedElements!B$2:B2974,1,FALSE)),"Not used","") | B7: poisson_ratio | C7: Poisson Ratio | D7: Ratio of the transverse contraction of a body to its longitudinal extension when stretched. Typical values in minerals are from 0.15 to 0.3 (Carbonates:0.15, Sandstones:0.2, Shales:0.25). | E7: double
A8: =IF(ISNA(VLOOKUP(B8,AssociatedElements!B$2:B2984,1,FALSE)),"Not used","") | B8: reflection_coefficient | C8: Reflection Coefficient | D8: the ratio of amplitude of the reflected wave to the incident wave | E8: double
A9: =IF(ISNA(VLOOKUP(B9,AssociatedElements!B$2:B2946,1,FALSE)),"Not used","") | B9: conductivity | C9: Electrical Conductivity | D9: A measure of the ability of a specified material to pass an electric current. | E9: double | F9: electric conductivity
A10: =IF(ISNA(VLOOKUP(B10,AssociatedElements!B$2:B2949,1,FALSE)),"Not used","") | B10: electric_field_x | C10: X Component of Electric Field | D10: The x component of an electric field. | E10: double | F10: electric field strength
A11: =IF(ISNA(VLOOKUP(B11,AssociatedElements!B$2:B2950,1,FALSE)),"Not used","") | B11: electric_field_y | C11: Y Component of Electric Field | D11: The y component of an electric field. | E11: double | F11: electric field strength
A12: =IF(ISNA(VLOOKUP(B12,AssociatedElements!B$2:B2951,1,FALSE)),"Not used","") | B12: electric_field_z | C12: Z Component of Electric Field | D12: The z component of an electric field. | E12: double | F12: electric field strength
A13: =IF(ISNA(VLOOKUP(B13,AssociatedElements!B$2:B2963,1,FALSE)),"Not used","") | B13: magnetic_field_total | C13: Total Field Strength | D13: Total strength of the magnetic field. | E13: double | F13: electric field strength
A14: =IF(ISNA(VLOOKUP(B14,AssociatedElements!B$2:B2964,1,FALSE)),"Not used","") | B14: magnetic_field_x | C14: X Component of Magnetic Field Strength | D14: The x component of a magnetic field. | E14: double | F14: electric field strength
A15: =IF(ISNA(VLOOKUP(B15,AssociatedElements!B$2:B2965,1,FALSE)),"Not used","") | B15: magnetic_field_y | C15: Y Component of Magnetic Field Strength | D15: The y component of a magnetic field. | E15: double | F15: electric field strength
A16: =IF(ISNA(VLOOKUP(B16,AssociatedElements!B$2:B2966,1,FALSE)),"Not used","") | B16: magnetic_field_z | C16: Z Component of Magnetic Field Strength | D16: The z component of a magnetic field. | E16: double | F16: electric field strength
A17: =IF(ISNA(VLOOKUP(B17,AssociatedElements!B$2:B2975,1,FALSE)),"Not used","") | B17: electrodiffusion_potential | C17: Electrodiffusion Potential | D17: A measure of transient background potentials that come from the difference in electrolyte mobilities within porous media | E17: double | F17: electric potential difference
A18: =IF(ISNA(VLOOKUP(B18,AssociatedElements!B$2:B2976,1,FALSE)),"Not used","") | B18: electric_potential | C18: Electric Potential | D18: A measure of the amount of work energy needed per unit of electric charge to move the charge from a reference point to a specific point in an electric field. | E18: double | F18: electric potential difference
A19: =IF(ISNA(VLOOKUP(B19,AssociatedElements!B$2:B2977,1,FALSE)),"Not used","") | B19: kinetic_potential | C19: Electrokinetic Potential | D19: A measure of the potential that forms from electrolytes flowing through a porous medium | E19: double | F19: electric potential difference
A20: =IF(ISNA(VLOOKUP(B20,AssociatedElements!B$2:B2978,1,FALSE)),"Not used","") | B20: mineral_potential | C20: Mineral Potential | D20: A measure of the potential from mineral deposit sources | E20: double | F20: electric potential difference
A21: =IF(ISNA(VLOOKUP(B21,AssociatedElements!B$2:B2979,1,FALSE)),"Not used","") | B21: nerst_potential | C21: Nerst Potential | D21: The potential difference between two electrodes immersed in a homogeonous medium in which local concentration differ | E21: double | F21: electric potential difference
A22: =IF(ISNA(VLOOKUP(B22,AssociatedElements!B$2:B2980,1,FALSE)),"Not used","") | B22: redox_potential | C22: Redox Potential | D22: A measure of the ability of chemical/biochemical systems to oxidize (lose electrons) or reduce (gain electrons). | E22: double | F22: electric potential difference
A23: =IF(ISNA(VLOOKUP(B23,AssociatedElements!B$2:B2991,1,FALSE)),"Not used","") | B23: spontaneous_potential | C23: Spontaneous Potential | D23: Also called self potential, is a naturally occurring electric potential difference in the Earth, measured by an electrode relative to a fixed reference electrode. Spontaneous potentials are usually caused by charge separation in clay or other minerals, due to presence of semi-permeable interface impeding the diffusion of ions through the pore space of rocks, or by natural flow of a conducting fluid through the rocks. | E23: double | F23: electric potential difference
A24: =IF(ISNA(VLOOKUP(B24,AssociatedElements!B$2:B3002,1,FALSE)),"Not used","") | B24: wall_amp | C24: Borehole Wall Amplitude | D24: amplitude of borehole wall signals | E24: double | F24: electric potential difference
A25: =IF(ISNA(VLOOKUP(B25,AssociatedElements!B$2:B2985,1,FALSE)),"Not used","") | B25: resistance | C25: Electrical Resistance | D25: The property by which a conductor opposes the flow of electrons, precisely electric current. It is the ratio of voltage to the electric current applied on an electronic device. Resistance is a physical property of the material, and hence, it depends upon the material type. It also depends upon the length and cross-sectional area of the material to which the current is applied. For a material, resistance is proportional to the length and inversely proportional to its cross-sectional area. | E25: double | F25: electric resistance
A26: =IF(ISNA(VLOOKUP(B26,AssociatedElements!B$2:B2998,1,FALSE)),"Not used","") | B26: tensor_impedance_x | C26: X Component of Tensor Impedance | D26: The x component of the magnetotelluric impedence tensor. | E26: double | F26: electric resistance
A27: =IF(ISNA(VLOOKUP(B27,AssociatedElements!B$2:B2999,1,FALSE)),"Not used","") | B27: tensor_impedance_y | C27: Y Component of Tensor Impedance | D27: The y component of the magnetotelluric impedence tensor. | E27: double | F27: electric resistance
A28: =IF(ISNA(VLOOKUP(B28,AssociatedElements!B$2:B3000,1,FALSE)),"Not used","") | B28: tensor_impedance_z | C28: Z Component of Tensor Impedance | D28: The z component of the magnetotelluric impedence tensor. | E28: double | F28: electric resistance
A29: =IF(ISNA(VLOOKUP(B29,AssociatedElements!B$2:B2986,1,FALSE)),"Not used","") | B29: resistivity | C29: Electrical Resistivity | D29: The resisting property of the material when the current is applied through it and is defined as the resistance per unit length for a unit cross-section of material. Resistivity is directly proportional to temperature. | E29: double | F29: electrical resistivity
A30: =IF(ISNA(VLOOKUP(B30,AssociatedElements!B$2:B2987,1,FALSE)),"Not used","") | B30: resistivity_app | C30: Apparent Resistivity | D30: Resistivity between electrodes. | E30: double | F30: electrical resistivity
A31: =IF(ISNA(VLOOKUP(B31,AssociatedElements!B$2:B2983,1,FALSE)),"Not used","") | B31: radiation_energy | C31: Radiation Energy | D31: Radiant energy emitted by radioactive source | E31: double | F31: energy
A32: =IF(ISNA(VLOOKUP(B32,AssociatedElements!B$2:B2997,1,FALSE)),"Not used","") | B32: tension | C32: Tension | D32: The force tending to cause extension of a body, as experienced in a cable, rope, string, etc. | E32: double | F32: force
A33: =IF(ISNA(VLOOKUP(B33,AssociatedElements!B$2:B2960,1,FALSE)),"Not used","") | B33: larmor_frequency | C33: Larmor Frequency | D33: The hydrogen proton excitation from specific magnetic field frequency based on Earth's field. | E33: double | F33: frequency
A34: =IF(ISNA(VLOOKUP(B34,AssociatedElements!B$2:B2971,1,FALSE)),"Not used","") | B34: number_beta_particles | C34: Number of Beta Particles | D34: The amount of detected beta particles in a given time. | E34: double | F34: frequency
A35: =IF(ISNA(VLOOKUP(B35,AssociatedElements!B$2:B2972,1,FALSE)),"Not used","") | B35: number_gamma_particles | C35: Number of Gamma Particles | D35: The amount of detected gamma particles in a given time. | E35: double | F35: frequency
A36: =IF(ISNA(VLOOKUP(B36,AssociatedElements!B$2:B2956,1,FALSE)),"Not used","") | B36: gravity_gradient | C36: Gravity Gradient | D36: The gradient in the gravitational forces acting on different parts of a nonspherical object. | E36: double | F36: gravitational gradient
A37: =IF(ISNA(VLOOKUP(B37,AssociatedElements!B$2:B2942,1,FALSE)),"Not used","") | B37: borehole_diameter | C37: Borehole Diameter | D37: The distance measured across an open borehole. | E37: double | F37: length
A38: =IF(ISNA(VLOOKUP(B38,AssociatedElements!B$2:B2952,1,FALSE)),"Not used","") | B38: em_velocity | C38: Electromagnetic Velocity | D38: The velocity of electromagnetic wave propagation through a medium. | E38: double | F38: length per time
A39: =IF(ISNA(VLOOKUP(B39,AssociatedElements!B$2:B2953,1,FALSE)),"Not used","") | B39: flow_velocity | C39: Flow Velocity | D39: The rate of vertical flow of a fluid within a borehole. | E39: double | F39: length per time
A40: =IF(ISNA(VLOOKUP(B40,AssociatedElements!B$2:B2973,1,FALSE)),"Not used","") | B40: p_wave_velocity | C40: Primary Compression Wave Velocity | D40: The velocity of a p-wave (Vp). P-waves (primary waves) are compressional waves that are longitudinal in nature. | E40: double | F40: length per time
...

Sheet AssociatedElements
A1: Start | B1: ID | C1: SourceElement | D1: ConditionalElement
A2: =IF(ISNA(VLOOKUP(B2,Definitions!B$2:B$1882,1,FALSE)),"Not listed","") | B2: attenuation | C2: //diggs:Property/diggs:propertyClass | D2: ancestor::diggs:measurement//diggs:procedure/diggs_geo:WirelineLog
A3: =IF(ISNA(VLOOKUP(B3,Definitions!B$2:B$1882,1,FALSE)),"Not listed","") | B3: borehole_diameter | C3: //diggs:Property/diggs:propertyClass | D3: ancestor::diggs:measurement//diggs:procedure/diggs_geo:WirelineLog
A4: =IF(ISNA(VLOOKUP(B4,Definitions!B$2:B$1882,1,FALSE)),"Not listed","") | B4: bulk_density | C4: //diggs:Property/diggs:propertyClass | D4: ancestor::diggs:measurement//diggs:procedure/diggs_geo:WirelineLog
A5: =IF(ISNA(VLOOKUP(B5,Definitions!B$2:B$1882,1,FALSE)),"Not listed","") | B5: compressional_slowness | C5: //diggs:Property/diggs:propertyClass | D5: ancestor::diggs:measurement//diggs:procedure/diggs_geo:WirelineLog
A6: =IF(ISNA(VLOOKUP(B6,Definitions!B$2:B$1882,1,FALSE)),"Not listed","") | B6: conductivity | C6: //diggs:Property/diggs:propertyClass | D6: ancestor::diggs:measurement//diggs:procedure/diggs_geo:WirelineLog
A7: =IF(ISNA(VLOOKUP(B7,Definitions!B$2:B$1882,1,FALSE)),"Not listed","") | B7: flow_velocity | C7: //diggs:Property/diggs:propertyClass | D7: ancestor::diggs:measurement//diggs:procedure/diggs_geo:WirelineLog
A8: =IF(ISNA(VLOOKUP(B8,Definitions!B$2:B$1882,1,FALSE)),"Not listed","") | B8: gamma_ray | C8: //diggs:Property/diggs:propertyClass | D8: ancestor::diggs:measurement//diggs:procedure/diggs_geo:WirelineLog
A9: =IF(ISNA(VLOOKUP(B9,Definitions!B$2:B$1882,1,FALSE)),"Not listed","") | B9: magnetic_susceptibility | C9: //diggs:Property/diggs:propertyClass | D9: ancestor::diggs:measurement//diggs:procedure/diggs_geo:WirelineLog
A10: =IF(ISNA(VLOOKUP(B10,Definitions!B$2:B$1882,1,FALSE)),"Not listed","") | B10: p_wave_velocity | C10: //diggs:Property/diggs:propertyClass | D10: ancestor::diggs:measurement//diggs:procedure/diggs_geo:WirelineLog
A11: =IF(ISNA(VLOOKUP(B11,Definitions!B$2:B$1882,1,FALSE)),"Not listed","") | B11: poisson_ratio | C11: //diggs:Property/diggs:propertyClass | D11: ancestor::diggs:measurement//diggs:procedure/diggs_geo:WirelineLog
A12: =IF(ISNA(VLOOKUP(B12,Definitions!B$2:B$1882,1,FALSE)),"Not listed","") | B12: resistance | C12: //diggs:Property/diggs:propertyClass | D12: ancestor::diggs:measurement//diggs:procedure/diggs_geo:WirelineLog
A13: =IF(ISNA(VLOOKUP(B13,Definitions!B$2:B$1882,1,FALSE)),"Not listed","") | B13: resistivity | C13: //diggs:Property/diggs:propertyClass | D13: ancestor::diggs:measurement//diggs:procedure/diggs_geo:WirelineLog
... A148: =IF(ISNA(VLOOKUP(B148,Definitions!B$2:B$1882,1,FALSE)),"Not listed","") | B148: TT | C148: //diggs:Property/diggs:propertyClass | D148: ancestor::diggs:measurement//diggs:procedure/diggs:GeophysicalProcessing/diggs:geophysicalMethod[text()="seismic refraction"]

Sheet Lists
A1: DataType | B1: DataType2 | C1: QuantityClass | D1: Column1 | M1: (amount of substance per time) per area
B2: anyURI | C2: absorbed dose | D2: =VLOOKUP(Table6[[#This Row],[QuantityClass]],M$1:M$175,1,FALSE) -> absorbed dose | M2: (energy per mass) per time
B3: base64binary | C3: activity [of radioactivity] | D3: =VLOOKUP(Table6[[#This Row],[QuantityClass]],M$1:M$175,1,FALSE) -> activity [of radioactivity] | M3: (mass per time) per area
B4: boolean | C4: amount of substance | D4: =VLOOKUP(Table6[[#This Row],[QuantityClass]],M$1:M$175,1,FALSE) -> amount of substance | M4: (mass per time) per length
B5: byte | C5: amount of substance per amount of substance | D5: =VLOOKUP(Table6[[#This Row],[QuantityClass]],M$1:M$175,1,FALSE) -> amount of substance per amount of substance | M5: (mass per volume) per length
B6: date | C6: amount of substance per area | D6: =VLOOKUP(Table6[[#This Row],[QuantityClass]],M$1:M$175,1,FALSE) -> amount of substance per area | M6: (volume per time) length
B7: dateTime | C7: amount of substance per mass | D7: =VLOOKUP(Table6[[#This Row],[QuantityClass]],M$1:M$175,1,FALSE) -> #N/A | E7: use for cation exchange capacity | M7: (volume per time) per (pressure length)
B8: decimal | C8: amount of substance per time | D8: =VLOOKUP(Table6[[#This Row],[QuantityClass]],M$1:M$175,1,FALSE) -> amount of substance per time | M8: (volume per time) per area
B9: double | C9: (amount of substance per time) per area | D9: =VLOOKUP(Table6[[#This Row],[QuantityClass]],M$1:M$175,1,FALSE) -> (amount of substance per time) per area | M9: (volume per time) per length
B10: duration | C10: amount of substance per volume | D10: =VLOOKUP(Table6[[#This Row],[QuantityClass]],M$1:M$175,1,FALSE) -> amount of substance per volume | M10: (volume per time) per pressure
B11: float | C11: angle per length | D11: =VLOOKUP(Table6[[#This Row],[QuantityClass]],M$1:M$175,1,FALSE) -> angle per length | M11: (volume per time) per time
B12: gDay | C12: angle per volume | D12: =VLOOKUP(Table6[[#This Row],[QuantityClass]],M$1:M$175,1,FALSE) -> angle per volume | M12: (volume per time) per volume
B13: gMonth | C13: angular acceleration | D13: =VLOOKUP(Table6[[#This Row],[QuantityClass]],M$1:M$175,1,FALSE) -> angular acceleration | M13: absorbed dose
B14: gMonthDay | C14: angular velocity | D14: =VLOOKUP(Table6[[#This Row],[QuantityClass]],M$1:M$175,1,FALSE) -> angular velocity | M14: activity [of radioactivity]
B15: gYear | C15: api gamma ray | D15: =VLOOKUP(Table6[[#This Row],[QuantityClass]],M$1:M$175,1,FALSE) -> API gamma ray | M15: amount of substance
B16: gYearMonth | C16: api gravity | D16: =VLOOKUP(Table6[[#This Row],[QuantityClass]],M$1:M$175,1,FALSE) -> API gravity | M16: amount of substance per amount of substance
B17: hexBinary | C17: api neutron | D17: =VLOOKUP(Table6[[#This Row],[QuantityClass]],M$1:M$175,1,FALSE) -> API neutron | M17: amount of substance per area
B18: integer | C18: area | D18: =VLOOKUP(Table6[[#This Row],[QuantityClass]],M$1:M$175,1,FALSE) -> area | M18: amount of substance per time
B19: language | C19: area per amount of substance | D19: =VLOOKUP(Table6[[#This Row],[QuantityClass]],M$1:M$175,1,FALSE) -> area per amount of substance | M19: amount of substance per volume
B20: long | C20: area per area | D20: =VLOOKUP(Table6[[#This Row],[QuantityClass]],M$1:M$175,1,FALSE) -> area per area | M20: angle per length
B21: negativeInteger | C21: area per count | D21: =VLOOKUP(Table6[[#This Row],[QuantityClass]],M$1:M$175,1,FALSE) -> #N/A | E21: In EML schema but not in EML dictionary | M21: angle per volume
B22: nonNegativeInteger | C22: area per mass | D22: =VLOOKUP(Table6[[#This Row],[QuantityClass]],M$1:M$175,1,FALSE) -> area per mass | M22: angular acceleration
B23: nonPositiveInteger | C23: area per time | D23: =VLOOKUP(Table6[[#This Row],[QuantityClass]],M$1:M$175,1,FALSE) -> area per time | M23: angular velocity
B24: normalizedString | C24: area per volume | D24: =VLOOKUP(Table6[[#This Row],[QuantityClass]],M$1:M$175,1,FALSE) -> area per volume | M24: API gamma ray
B25: positiveInteger | C25: attenuation per frequency interval | D25: =VLOOKUP(Table6[[#This Row],[QuantityClass]],M$1:M$175,1,FALSE) -> attenuation per frequency interval | M25: API gravity
B26: short | C26: capacitance | D26: =VLOOKUP(Table6[[#This Row],[QuantityClass]],M$1:M$175,1,FALSE) -> capacitance | M26: API neutron
B27: string | C27: data transfer speed | D27: =VLOOKUP(Table6[[#This Row],[QuantityClass]],M$1:M$175,1,FALSE) -> data transfer speed | M27: area
B28: string | C28: diffusion coefficient | D28: =VLOOKUP(Table6[[#This Row],[QuantityClass]],M$1:M$175,1,FALSE) -> diffusion coefficient | M28: area per amount of substance
B29: time | C29: diffusive time of flight | D29: =VLOOKUP(Table6[[#This Row],[QuantityClass]],M$1:M$175,1,FALSE) -> #N/A | E29: In EML schema but not in EML dictionary | M29: area per area
B30: token | C30: digital storage | D30: =VLOOKUP(Table6[[#This Row],[QuantityClass]],M$1:M$175,1,FALSE) -> digital storage | M30: area per mass
B31: unsignedByte | C31: dimensionless | D31: =VLOOKUP(Table6[[#This Row],[QuantityClass]],M$1:M$175,1,FALSE) -> dimensionless | M31: area per time
B32: unsignedInt | C32: dipole moment | D32: =VLOOKUP(Table6[[#This Row],[QuantityClass]],M$1:M$175,1,FALSE) -> dipole moment | M32: area per volume
B33: unsignedLong | C33: dose equivalent | D33: =VLOOKUP(Table6[[#This Row],[QuantityClass]],M$1:M$175,1,FALSE) -> dose equivalent | M33: attenuation per frequency interval
B34: unsignedShort | C34: dynamic viscosity | D34: =VLOOKUP(Table6[[#This Row],[QuantityClass]],M$1:M$175,1,FALSE) -> dynamic viscosity | M34: capacitance
B35: vector | C35: electric charge | D35: =VLOOKUP(Table6[[#This Row],[QuantityClass]],M$1:M$175,1,FALSE) -> electric charge | M35: data transfer speed
C36: electric charge per area | D36: =VLOOKUP(Table6[[#This Row],[QuantityClass]],M$1:M$175,1,FALSE) -> electric charge per area | M36: diffusion coefficient
C37: electric charge per mass | D37: =VLOOKUP(Table6[[#This Row],[QuantityClass]],M$1:M$175,1,FALSE) -> electric charge per mass | M37: digital storage
C38: electric charge per volume | D38: =VLOOKUP(Table6[[#This Row],[QuantityClass]],M$1:M$175,1,FALSE) -> electric charge per volume | M38: dimensionless
C39: electric conductance | D39: =VLOOKUP(Table6[[#This Row],[QuantityClass]],M$1:M$175,1,FALSE) -> electric conductance | M39: dipole moment
C40: electric conductivity | D40: =VLOOKUP(Table6[[#This Row],[QuantityClass]],M$1:M$175,1,FALSE) -> electric conductivity | M40: dose equivalent
...
