Workbook

Sheet DictionaryName
A1: Start | B1: Dictionary ID | C1: DictionaryFile | D1: DictionaryName | E1: Description
E2: Leave this line blank
B3: propertyClass | C3: gr_inj_properties | D3: DIGGS Grout Injection Properties | E3: Dictionary defining the values for recorded grout injection properties for both staged and continuous grouting activities. These values are used in the propertyClass property of the "GroutinjectionProperty" and "ContinuousGroutInjectionProperty" objects.

Sheet Definitions
A1: Start | B1: ID | C1: Name | D1: Description | E1: DataType | F1: QuantityClass | G1: Authority | H1: Reference
A2: =IF(ISNA(VLOOKUP(B2,AssociatedElements!B$2:B423,1,FALSE)),"Not used","") | B2: apparent_lugeon_value | C2: apparent lugeon value | D2: Measure of permeability via in-site pressure testing | E2: double | F2: dimensionless
A3: =IF(ISNA(VLOOKUP(B3,AssociatedElements!B$2:B424,1,FALSE)),"Not used","") | B3: column_pressure | C3: column pressure | D3: Calculated hydrostatic pressure on borehole wall | E3: double | F3: pressure
A4: =IF(ISNA(VLOOKUP(B4,AssociatedElements!B$2:B425,1,FALSE)),"Not used","") | B4: crowd_pressure | C4: crowd pressure | D4: Downward hydraulic pressure of the drill (not at the bit) | E4: double | F4: pressure
A5: =IF(ISNA(VLOOKUP(B5,AssociatedElements!B$2:B426,1,FALSE)),"Not used","") | B5: depth | C5: depth | D5: Depth of the monitor at a specific time instance | E5: double | F5: length
A6: =IF(ISNA(VLOOKUP(B6,AssociatedElements!B$2:B427,1,FALSE)),"Not used","") | B6: drilling_index | C6: drilling index | D6: Measure of bit performance calculated using a number of dimensionless parameters | E6: double | F6: dimensionless
A7: =IF(ISNA(VLOOKUP(B7,AssociatedElements!B$2:B428,1,FALSE)),"Not used","") | B7: drilling_speed | C7: drilling speed | D7: Advance rate of the monitor while drilling downward | E7: double | F7: length per time
A8: =IF(ISNA(VLOOKUP(B8,AssociatedElements!B$2:B429,1,FALSE)),"Not used","") | B8: effective_pressure | C8: effective pressure | D8: Pressure felt at injection point (pressure at pump - line loss) | E8: double | F8: pressure
A9: =IF(ISNA(VLOOKUP(B9,AssociatedElements!B$2:B430,1,FALSE)),"Not used","") | B9: elapsed_time | C9: elapsed time | D9: Amount of time since start of an injection period | E9: double | F9: time
A10: =IF(ISNA(VLOOKUP(B10,AssociatedElements!B$2:B431,1,FALSE)),"Not used","") | B10: fluid_1_flow | C10: fluid 1 flow | D10: Rate of flow of the fluid 1 component (either water or air) as defined in the instance | E10: double | F10: volume per time
A11: =IF(ISNA(VLOOKUP(B11,AssociatedElements!B$2:B432,1,FALSE)),"Not used","") | B11: fluid_1_pressure | C11: fluid 1 pressure | D11: Pressure reading of fluid 1 during injection | E11: double | F11: pressure
A12: =IF(ISNA(VLOOKUP(B12,AssociatedElements!B$2:B433,1,FALSE)),"Not used","") | B12: fluid_1_temperature | C12: fluid 1 temperature | D12: Temperature of fluid 1 | E12: double | F12: thermodynamic temperature
A13: =IF(ISNA(VLOOKUP(B13,AssociatedElements!B$2:B434,1,FALSE)),"Not used","") | B13: fluid_2_flow | C13: fluid 2 flow | D13: Rate of flow of the fluid 2 component (either water or air) as defined in the instance | E13: double | F13: volume per time
... A26: =IF(ISNA(VLOOKUP(B26,AssociatedElements!B$2:B447,1,FALSE)),"Not used","") | B26: micro_motion_volume | C26: micro motion volume | D26: Volume of grout measured by Micro Motion branded sensor | E26: double | F26: volume
A27: =IF(ISNA(VLOOKUP(B27,AssociatedElements!B$2:B448,1,FALSE)),"Not used","") | B27: mix | C27: grout mix ID | D27: Identifer for the grout mix used | E27: string
A28: =IF(ISNA(VLOOKUP(B28,AssociatedElements!B$2:B449,1,FALSE)),"Not used","") | B28: packer_pressure | C28: packer pressure | D28: Pressure within the packer | E28: double | F28: pressure
A29: =IF(ISNA(VLOOKUP(B29,AssociatedElements!B$2:B450,1,FALSE)),"Not used","") | B29: pull_speed | C29: pull speed | D29: Lift rate of the monitor while grouting | E29: double | F29: length per time
A30: =IF(ISNA(VLOOKUP(B30,AssociatedElements!B$2:B451,1,FALSE)),"Not used","") | B30: rotary_pressure | C30: rotary pressure | D30: Hydraulic system pressure to spin the drill steel | E30: double | F30: pressure
A31: =IF(ISNA(VLOOKUP(B31,AssociatedElements!B$2:B452,1,FALSE)),"Not used","") | B31: rotation_speed | C31: rotation speed | D31: Rotational velocity of the monitor | E31: double | F31: angular velocity
A32: =IF(ISNA(VLOOKUP(B32,AssociatedElements!B$2:B453,1,FALSE)),"Not used","") | B32: specific_energy | C32: specific energy | D32: Pressure times flow divided by lift rate. Pressure can be measured at the pump or at the drill rig and is not measured at the nozzle. Lift rate is average uplift distance per unit time. Pressure at the pump can be affected by line type, size, and distance to the rig for constant applied pressure. The energy of the air is usually negligible in this calculation, but does contribute significantly to column diameter. This parameter can be graphed to quickly check jetting records and can be correlated to diameter for all other aspects (especially number of fluids) staying constant during the test program. | E32: double | F32: energy per length
A33: =IF(ISNA(VLOOKUP(B33,AssociatedElements!B$2:B454,1,FALSE)),"Not used","") | B33: stroke_count | C33: stroke count | D33: The number of strokes of the pump piston | E33: integer | F33: dimensionless
A34: =IF(ISNA(VLOOKUP(B34,AssociatedElements!B$2:B455,1,FALSE)),"Not used","") | B34: take | C34: grout take | D34: Total volume of grout injected | E34: double | F34: volume
A35: =IF(ISNA(VLOOKUP(B35,AssociatedElements!B$2:B456,1,FALSE)),"Not used","") | B35: thrust | C35: thrust | D35: Downward force of the drill | E35: double | F35: force
A36: =IF(ISNA(VLOOKUP(B36,AssociatedElements!B$2:B457,1,FALSE)),"Not used","") | B36: torque | C36: torque | D36: Rotational force of the drill | E36: double | F36: moment of force
A37: =IF(ISNA(VLOOKUP(B37,AssociatedElements!B$2:B458,1,FALSE)),"Not used","") | B37: time | C37: time | D37: Time instant of measurement | E37: time | F37: time
B38: volume_overconsumption | C38: Volume overconsumption | D38: The ratio of actual to theoretical grout or concrete volume placed at a given depth during installation, expressed as a percentage - the depth-indexed counterpart to a Menard CMC installation record (GIW p.42). A GENUINE COVERAGE QUANTITY, NOT A REPEAT OF A COLUMN-LEVEL COMPUTATION: RIColumnType already carries theoreticalGroutVolume and placedGroutVolume, so the whole-column overconsumption ratio is derivable from those two without this entry - but that derived ratio cannot say WHERE along the column the overconsumption occurred, which is what a Menard-style rig log actually records and what a reviewer needs to see a void, a soft layer or a loss zone. Carry both: the column-level total on RIColumnType is the separate, out-of-scope-for-this-entry summary; this entry is the per-reading value that makes the profile against depth expressible at all. | E38: double | F38: dimensionless
B39: grout_level | C39: grout level | D39: The elevation or depth of the grout surface within the column bore or annulus at a given reading, used to detect an in-progress drop in grout level - a sign the column is losing grout into the surrounding ground and is at risk of an 'uncovered column' condition (V2 Installation row 31). Where a drop triggers a corrective action, that outcome is recorded separately as diggs:RIColumnConstructionType/groutLevelCorrectiveAction; this entry carries only the level reading itself. | E39: double | F39: length
B40: grout_return_volume | C40: Grout return (wet-squeeze) volume | D40: The volume of grout or slurry returning to the surface during installation - a 'wet squeeze' - distinct from volume_overconsumption (excess grout pumped versus theoretical, in-bore and depth-indexed): this is fluid actually emerging at the surface, and is often observed at an already-installed neighbouring column rather than the one currently being drilled or grouted. Where that is the case, record this reading against whichever column's installationRecord the observer is logging against, and use remark to note which column the return was actually attributed to if it differs (V2 Installation row 32). | E40: double | F40: volume

Sheet AssociatedElements
A1: Start | B1: ID | C1: SourceElement | D1: ConditionalElement | E1: Column1
A2: =IF(ISNA(VLOOKUP(B2,Definitions!B$2:B$1843,1,FALSE)),"Not listed","") | B2: apparent_lugeon_value | C2: //diggs:propertyClass | D2: ancestor::diggs:GroutStage
A3: =IF(ISNA(VLOOKUP(B3,Definitions!B$2:B$1843,1,FALSE)),"Not listed","") | B3: column_pressure | C3: //diggs:propertyClass | D3: ancestor::diggs:GroutStage
A4: =IF(ISNA(VLOOKUP(B4,Definitions!B$2:B$1843,1,FALSE)),"Not listed","") | B4: crowd_pressure | C4: //diggs:propertyClass | D4: ancestor::diggs:ContinuousGrouting
A5: =IF(ISNA(VLOOKUP(B5,Definitions!B$2:B$1843,1,FALSE)),"Not listed","") | B5: depth | C5: //diggs:propertyClass | D5: ancestor::diggs:ContinuousGrouting
A6: =IF(ISNA(VLOOKUP(B6,Definitions!B$2:B$1843,1,FALSE)),"Not listed","") | B6: drilling_index | C6: //diggs:propertyClass | D6: ancestor::diggs:ContinuousGrouting
A7: =IF(ISNA(VLOOKUP(B7,Definitions!B$2:B$1843,1,FALSE)),"Not listed","") | B7: drilling_speed | C7: //diggs:propertyClass | D7: ancestor::diggs:ContinuousGrouting
A8: =IF(ISNA(VLOOKUP(B8,Definitions!B$2:B$1843,1,FALSE)),"Not listed","") | B8: effective_pressure | C8: //diggs:propertyClass | D8: ancestor::diggs:GroutStage
A9: =IF(ISNA(VLOOKUP(B9,Definitions!B$2:B$1843,1,FALSE)),"Not listed","") | B9: elapsed_time | C9: //diggs:propertyClass | D9: ancestor::diggs:GroutStage
A10: =IF(ISNA(VLOOKUP(B10,Definitions!B$2:B$1843,1,FALSE)),"Not listed","") | B10: elapsed_time | C10: //diggs:propertyClass | D10: ancestor::diggs:ContinuousGrouting
A11: =IF(ISNA(VLOOKUP(B11,Definitions!B$2:B$1843,1,FALSE)),"Not listed","") | B11: fluid_1_flow | C11: //diggs:propertyClass | D11: ancestor::diggs:ContinuousGrouting
A12: =IF(ISNA(VLOOKUP(B12,Definitions!B$2:B$1843,1,FALSE)),"Not listed","") | B12: fluid_1_pressure | C12: //diggs:propertyClass | D12: ancestor::diggs:ContinuousGrouting
A13: =IF(ISNA(VLOOKUP(B13,Definitions!B$2:B$1843,1,FALSE)),"Not listed","") | B13: fluid_1_temperature | C13: //diggs:propertyClass | D13: ancestor::diggs:ContinuousGrouting
... A38: =IF(ISNA(VLOOKUP(B38,Definitions!B$2:B$1843,1,FALSE)),"Not listed","") | B38: stroke_count | C38: //diggs:propertyClass | D38: ancestor::diggs:ContinuousGrouting
A39: =IF(ISNA(VLOOKUP(B39,Definitions!B$2:B$1843,1,FALSE)),"Not listed","")
A40: =IF(ISNA(VLOOKUP(B40,Definitions!B$2:B$1843,1,FALSE)),"Not listed","") | B40: take | C40: //diggs:propertyClass | D40: ancestor::diggs:GroutStage
A41: =IF(ISNA(VLOOKUP(B41,Definitions!B$2:B$1843,1,FALSE)),"Not listed","") | B41: take | C41: //diggs:propertyClass | D41: ancestor::diggs:ContinuousGrouting
A42: =IF(ISNA(VLOOKUP(B42,Definitions!B$2:B$1843,1,FALSE)),"Not listed","") | B42: thrust | C42: //diggs:propertyClass | D42: ancestor::diggs:ContinuousGrouting
A43: =IF(ISNA(VLOOKUP(B43,Definitions!B$2:B$1843,1,FALSE)),"Not listed","") | B43: time | C43: //diggs:propertyClass | D43: ancestor::diggs:ContinuousGrouting
A44: =IF(ISNA(VLOOKUP(B44,Definitions!B$2:B$1843,1,FALSE)),"Not listed","") | B44: time | C44: //diggs:propertyClass | D44: ancestor::diggs:GroutStage
A45: =IF(ISNA(VLOOKUP(B45,Definitions!B$2:B$1843,1,FALSE)),"Not listed","") | B45: torque | C45: //diggs:propertyClass | D45: ancestor::diggs:ContinuousGrouting
A46: =IF(ISNA(VLOOKUP(B46,Definitions!B$2:B$1843,1,FALSE)),"Not listed","") | B46: pull_speed | C46: //diggs:propertyClass | D46: ancestor::diggs:constructionActivity//diggs:RIInstallationRecord
A47: =IF(ISNA(VLOOKUP(B47,Definitions!B$2:B$1843,1,FALSE)),"Not listed","") | B47: grout_pressure | C47: //diggs:propertyClass | D47: ancestor::diggs:constructionActivity//diggs:RIInstallationRecord
A48: =IF(ISNA(VLOOKUP(B48,Definitions!B$2:B$1843,1,FALSE)),"Not listed","") | B48: grout_flow | C48: //diggs:propertyClass | D48: ancestor::diggs:constructionActivity//diggs:RIInstallationRecord
A49: =IF(ISNA(VLOOKUP(B49,Definitions!B$2:B$1843,1,FALSE)),"Not listed","") | B49: grout_volume | C49: //diggs:propertyClass | D49: ancestor::diggs:constructionActivity//diggs:RIInstallationRecord
A50: =IF(ISNA(VLOOKUP(B50,Definitions!B$2:B$1843,1,FALSE)),"Not listed","") | B50: stroke_count | C50: //diggs:propertyClass | D50: ancestor::diggs:constructionActivity//diggs:RIInstallationRecord
A51: =IF(ISNA(VLOOKUP(B51,Definitions!B$2:B$1843,1,FALSE)),"Not listed","") | B51: drilling_speed | C51: //diggs:propertyClass | D51: ancestor::diggs:constructionActivity//diggs:RIInstallationRecord
... A58: =IF(ISNA(VLOOKUP(B58,Definitions!B$2:B$1843,1,FALSE)),"Not listed","") | B58: grout_return_volume | C58: //diggs:propertyClass | D58: ancestor::diggs:constructionActivity//diggs:RIInstallationRecord
B59: apparent_lugeon_value | C59: //diggs:recordingParameter | D59: ancestor::diggs:ConstructionActivitySpecification
B60: column_pressure | C60: //diggs:recordingParameter | D60: ancestor::diggs:ConstructionActivitySpecification
B61: crowd_pressure | C61: //diggs:recordingParameter | D61: ancestor::diggs:ConstructionActivitySpecification
B62: depth | C62: //diggs:recordingParameter | D62: ancestor::diggs:ConstructionActivitySpecification
B63: drilling_index | C63: //diggs:recordingParameter | D63: ancestor::diggs:ConstructionActivitySpecification
B64: drilling_speed | C64: //diggs:recordingParameter | D64: ancestor::diggs:ConstructionActivitySpecification
B65: effective_pressure | C65: //diggs:recordingParameter | D65: ancestor::diggs:ConstructionActivitySpecification
B66: elapsed_time | C66: //diggs:recordingParameter | D66: ancestor::diggs:ConstructionActivitySpecification
B67: fluid_1_flow | C67: //diggs:recordingParameter | D67: ancestor::diggs:ConstructionActivitySpecification
B68: fluid_1_pressure | C68: //diggs:recordingParameter | D68: ancestor::diggs:ConstructionActivitySpecification
B69: fluid_1_temperature | C69: //diggs:recordingParameter | D69: ancestor::diggs:ConstructionActivitySpecification
B70: fluid_2_flow | C70: //diggs:recordingParameter | D70: ancestor::diggs:ConstructionActivitySpecification
...

Sheet AlternateNames
A1: Start | B1: ID | C1: Name | D1: codeSpace
A2: =IF(ISNA(VLOOKUP(B2,Definitions!B$2:B$1839,1,FALSE)),"Not listed","") | B2: LFS | C2: An alternate name for the definition code given in ID | D2: A URI to provide context for the name. Typically this might identify an authority, a language. a dictionary, or some other metadata value
A3: =IF(ISNA(VLOOKUP(B3,Definitions!B$2:B$1839,1,FALSE)),"Not listed","") | B3: pull_speed | C3: withdrawal rate

Sheet Lists
A1: DataType | B1: DataType2 | C1: QuantityClass
B2: anyURI | C2: absorbed dose
B3: base64binary | C3: activity of radioactivity
B4: boolean | C4: amount of substance
B5: byte | C5: amount of substance per amount of substance
B6: date | C6: amount of substance per area
B7: dateTime | C7: amount of substance per time
B8: decimal | C8: amount of substance per time per area
B9: double | C9: amount of substance per volume
B10: duration | C10: angle per length
B11: float | C11: angle per volume
B12: gDay | C12: angular acceleration
B13: gMonth | C13: angular velocity
... B17: hexBinary | C17: area
C18: area per amount of substance
B19: integer | C19: area per area
B20: language | C20: area per count
B21: long | C21: area per mass
B22: negativeInteger | C22: area per time
B23: nonNegativeInteger | C23: area per volume
B24: nonPositiveInteger | C24: attenuation per frequency interval
B25: normalizedString | C25: capacitance
B26: positiveInteger | C26: cation exchange capacity
B27: short | C27: data transfer speed
B28: string | C28: density or unit weight
C29: diffusion coefficient
B30: time | C30: diffusive time of flight
B31: token | C31: digital storage
B32: unsignedByte | C32: dimensionless
B33: unsignedInt | C33: dipole moment
B34: unsignedLong | C34: dose equivalent
B35: unsignedShort | C35: dynamic viscosity
B36: vector | C36: electric charge
C37: electric charge per area
C38: electric charge per mass
C39: electric charge per volume
C40: electric conductance
C41: electric conductivity
C42: electric current
C43: electric current density
...
