Workbook

Sheet DictionaryName
A1: Start | B1: Dictionary ID | C1: DictionaryFile | D1: DictionaryName | E1: Description
E2: Leave this line blank
B3: measurementKind | C3: measurementKind | D3: DIGGS Design Measurement Kind Codelist Definitions | E3: Codes naming the kind of measurement a diggs:DesignMeasurement plans, for use where no measurementMethod is cited or where the cited method admits several kinds of measurement. Seeded here with the load-verification and integrity-testing kinds referenced by rigid inclusion acceptance testing (ASIRI; FHWA-KS-25-02); DesignMeasurement is general DIGGS infrastructure covering every planned Test, Monitor, MaterialTest, MeasurementWhileDrilling and GeophysicalFieldSurvey, so the list is expected to grow well beyond this starting set as other domains populate it. Expect this element to be omitted in the common case, per its own documentation.

Sheet Definitions
A1: Start | B1: ID | C1: Name | D1: Description | E1: DataType | F1: QuantityClass | G1: Authority | H1: Reference
A2: =IF(ISNA(VLOOKUP(B2,AssociatedElements!B$2:B$999,1,FALSE)),"Not used","") | B2: static_load_test | C2: Static load test | D2: A slow-maintained or constant-rate-of-penetration axial load test applying load directly to the element and measuring load-movement response, per ASTM D1143 or equivalent. | E2: string | G2: ASTM D1143
A3: =IF(ISNA(VLOOKUP(B3,AssociatedElements!B$2:B$999,1,FALSE)),"Not used","") | B3: rapid_load_test | C3: Rapid load test | D3: An axial load test applying load over roughly one to several seconds, faster than a static test and slower than a dynamic impact test, per ASTM D7383 or equivalent. | E3: string | G3: ASTM D7383
A4: =IF(ISNA(VLOOKUP(B4,AssociatedElements!B$2:B$999,1,FALSE)),"Not used","") | B4: dynamic_load_test | C4: High-strain dynamic load test | D4: An axial load test in which the element is struck by an impact device and force and velocity are measured to estimate capacity by wave-equation analysis, per ASTM D4945 or equivalent. | E4: string | G4: ASTM D4945
A5: =IF(ISNA(VLOOKUP(B5,AssociatedElements!B$2:B$999,1,FALSE)),"Not used","") | B5: pile_integrity_test | C5: Pile integrity test (PIT) | D5: A low-strain impact (pulse-echo or transient-response) test used to detect discontinuities, necking or changes in cross-section along the length of a completed pile or column, per ASTM D5882 or equivalent. | E5: string | G5: ASTM D5882
A6: =IF(ISNA(VLOOKUP(B6,AssociatedElements!B$2:B$999,1,FALSE)),"Not used","") | B6: lateral_load_test | C6: Lateral load test | D6: A test applying lateral load to the element and measuring lateral load-deflection response, per ASTM D3966 or equivalent. | E6: string | G6: ASTM D3966
A7: =IF(ISNA(VLOOKUP(B7,AssociatedElements!B$2:B$999,1,FALSE)),"Not used","") | B7: plate_load_test | C7: Plate load test | D7: A plate-bearing load test on a single deep foundation element head, measuring ground or platform stiffness rather than the element's own axial capacity, per ASTM D1194 (withdrawn 2003, still in practical use), ASTM D1195/D1196, or DIN 18134. | E7: string | G7: ASTM D1196
A8: =IF(ISNA(VLOOKUP(B8,AssociatedElements!B$2:B$999,1,FALSE)),"Not used","") | B8: zone_load_test | C8: Zone load test | D8: A large-plate load test on a load transfer platform over a group of columns, treating the group and the intervening soil as a composite rather than testing one element - applied to the platform as a sampling feature, not to a pile. Per BS 8006-1 (which requires the test), typically executed to ASTM D1195/D1196 or DIN 18134's methodology. | E8: string | G8: BS 8006-1
A9: =IF(ISNA(VLOOKUP(B9,AssociatedElements!B$2:B$999,1,FALSE)),"Not used","") | B9: thermal_integrity_profiling | C9: Thermal integrity profiling | D9: A thermal integrity test that relates the heat of hydration generated by curing concrete along a completed element's length to its as-built cross-section and continuity, per ASTM D7949. | E9: string | G9: ASTM D7949
A10: =IF(ISNA(VLOOKUP(B10,AssociatedElements!B$2:B$999,1,FALSE)),"Not used","") | B10: aggregate_abrasion_value_test | C10: Aggregate abrasion value test | D10: Measures the resistance of an aggregate to surface wear, as the percentage mass loss of chippings pressed against a rotating steel disc with sand as abrasive, after 500 revolutions. | E10: string | G10: DIGGS
A11: =IF(ISNA(VLOOKUP(B11,AssociatedElements!B$2:B$999,1,FALSE)),"Not used","") | B11: aggregate_crushing_value_test | C11: Aggregate crushing value test | D11: Gives a relative measure of an aggregate's resistance to crushing under a gradually applied compressive load, as the percentage of fines passing the specified sieve. | E11: string | G11: DIGGS
A12: =IF(ISNA(VLOOKUP(B12,AssociatedElements!B$2:B$999,1,FALSE)),"Not used","") | B12: aggregate_elongation_index_test | C12: Aggregate elongation index test | D12: Percentage by weight of aggregate particles whose greatest dimension is 1.8 times their mean dimension, for aggregates larger than 6.3 mm. | E12: string | G12: DIGGS
A13: =IF(ISNA(VLOOKUP(B13,AssociatedElements!B$2:B$999,1,FALSE)),"Not used","") | B13: aggregate_flakiness_index_test | C13: Aggregate flakiness index test | D13: Percentage by weight of aggregate particles whose least dimension is less than 0.6 times their mean size. | E13: string | G13: DIGGS
... A89: =IF(ISNA(VLOOKUP(B89,AssociatedElements!B$2:B$999,1,FALSE)),"Not used","") | B89: wireline_log | C89: Wireline log | D89: Geophysical test data collected by wireline (borehole logging) methods. | E89: string | G89: DIGGS

Sheet AssociatedElements
A1: Start | B1: ID | C1: SourceElement | D1: ConditionalElement
A2: =IF(ISNA(VLOOKUP(B2,Definitions!B$2:B$999,1,FALSE)),"Not listed","") | B2: static_load_test | C2: //diggs:DesignMeasurement/diggs:measurementKind
A3: =IF(ISNA(VLOOKUP(B3,Definitions!B$2:B$999,1,FALSE)),"Not listed","") | B3: rapid_load_test | C3: //diggs:DesignMeasurement/diggs:measurementKind
A4: =IF(ISNA(VLOOKUP(B4,Definitions!B$2:B$999,1,FALSE)),"Not listed","") | B4: dynamic_load_test | C4: //diggs:DesignMeasurement/diggs:measurementKind
A5: =IF(ISNA(VLOOKUP(B5,Definitions!B$2:B$999,1,FALSE)),"Not listed","") | B5: pile_integrity_test | C5: //diggs:DesignMeasurement/diggs:measurementKind
A6: =IF(ISNA(VLOOKUP(B6,Definitions!B$2:B$999,1,FALSE)),"Not listed","") | B6: lateral_load_test | C6: //diggs:DesignMeasurement/diggs:measurementKind
A7: =IF(ISNA(VLOOKUP(B7,Definitions!B$2:B$999,1,FALSE)),"Not listed","") | B7: plate_load_test | C7: //diggs:DesignMeasurement/diggs:measurementKind
A8: =IF(ISNA(VLOOKUP(B8,Definitions!B$2:B$999,1,FALSE)),"Not listed","") | B8: zone_load_test | C8: //diggs:DesignMeasurement/diggs:measurementKind
A9: =IF(ISNA(VLOOKUP(B9,Definitions!B$2:B$999,1,FALSE)),"Not listed","") | B9: thermal_integrity_profiling | C9: //diggs:DesignMeasurement/diggs:measurementKind
A10: =IF(ISNA(VLOOKUP(B10,Definitions!B$2:B$999,1,FALSE)),"Not listed","") | B10: aggregate_abrasion_value_test | C10: //diggs:DesignMeasurement/diggs:measurementKind
A11: =IF(ISNA(VLOOKUP(B11,Definitions!B$2:B$999,1,FALSE)),"Not listed","") | B11: aggregate_crushing_value_test | C11: //diggs:DesignMeasurement/diggs:measurementKind
A12: =IF(ISNA(VLOOKUP(B12,Definitions!B$2:B$999,1,FALSE)),"Not listed","") | B12: aggregate_elongation_index_test | C12: //diggs:DesignMeasurement/diggs:measurementKind
A13: =IF(ISNA(VLOOKUP(B13,Definitions!B$2:B$999,1,FALSE)),"Not listed","") | B13: aggregate_flakiness_index_test | C13: //diggs:DesignMeasurement/diggs:measurementKind
... A89: =IF(ISNA(VLOOKUP(B89,Definitions!B$2:B$999,1,FALSE)),"Not listed","") | B89: wireline_log | C89: //diggs:DesignMeasurement/diggs:measurementKind

Sheet AlternateNames
A1: Start | B1: ID | C1: Name | D1: codeSpace
A2: =IF(ISNA(VLOOKUP(B2,Definitions!B$2:B$1839,1,FALSE)),"Not listed","") | B2: LFS | C2: An alternate name for the definition code given in ID | D2: A URI to provide context for the name. Typically this might identify an authority, a language. a dictionary, or some other metadata value

Sheet Lists
A1: DataType | B1: DataType2 | C1: QuantityClass | D1: Column2 | E1: Column3
B2: anyURI | C2: absorbed dose
B3: base64binary | C3: activity [of radioactivity]
B4: boolean | C4: amount of substance
B5: byte | C5: amount of substance per amount of substance
B6: date | C6: amount of substance per area
B7: dateTime | C7: amount of substance per mass | D7: use for cation exchange capacity | E7: not yet used nor in EML Dictionary
B8: decimal | C8: amount of substance per time
B9: double | C9: (amount of substance per time) per area
B10: duration | C10: amount of substance per volume
B11: float | C11: angle per length
B12: gDay | C12: angle per volume
B13: gMonth | C13: angular acceleration
B14: gMonthDay | C14: angular velocity
B15: gYear | C15: api gamma ray
B16: gYearMonth | C16: api gravity
B17: hexBinary | C17: api neutron
B18: integer | C18: area
B19: language | C19: area per amount of substance
B20: long | C20: area per area
B21: negativeInteger | C21: area per count | D21: In EML schema but not in EML dictionary
B22: nonNegativeInteger | C22: area per mass
B23: nonPositiveInteger | C23: area per time
B24: normalizedString | C24: area per volume
B25: positiveInteger | C25: attenuation per frequency interval
B26: short | C26: capacitance
B27: string | C27: data transfer speed
B28: string | C28: diffusion coefficient
B29: time | C29: diffusive time of flight | D29: In EML schema but not in EML dictionary
B30: token | C30: digital storage
B31: unsignedByte | C31: dimensionless
B32: unsignedInt | C32: dipole moment
B33: unsignedLong | C33: dose equivalent
B34: unsignedShort | C34: dynamic viscosity
B35: vector | C35: electric charge
C36: electric charge per area
C37: electric charge per mass
C38: electric charge per volume
C39: electric conductance
C40: electric conductivity
...
