Workbook

Sheet DictionaryName
A1: Start | B1: Dictionary ID | C1: DictionaryFile | D1: DictionaryName | E1: Description
E2: Leave this line blank
B3: propertyClass | C3: mwd_properties | D3: DIGGS Measurement Properties for MWD | E3: This dictionary contains the values for the propertyClass property contained within the the Measurement While Drilling measurement object (diggs:/MeasurementWhileDrilling).

Sheet Definitions
A1: Start | B1: ID | C1: Name | D1: Description | E1: DataType | F1: QuantityClass | G1: Authority | H1: Reference
A2: =IF(ISNA(VLOOKUP(B2,AssociatedElements!B$2:B2859,1,FALSE)),"Not used","") | B2: alteration_index | C2: Alteration index | D2: A value of relative hardness as a function of crowd and penetration rate, as defined by Pfister, 1985. | E2: double | G2: Pfister, P. 1985. “Recording Drilling Parameters in Ground Engineering.” Journal of Ground Engineering, 18(3), 16–21. | H2: https://emap-romulus-prod.s3.eu-west-1.amazonaws.com/wp-content/uploads/sites/13/1985/04/1985-04_Pages_16-21.pdf
A3: =IF(ISNA(VLOOKUP(B3,AssociatedElements!B$2:B2868,1,FALSE)),"Not used","") | B3: calibration_flag | C3: Calibration flag | D3: True-False Flag; true if this is a calibration test | E3: boolean
A4: =IF(ISNA(VLOOKUP(B4,AssociatedElements!B$2:B2825,1,FALSE)),"Not used","") | B4: crowd_downward_thrust | C4: Crowd or downward thrust | D4: Crowd or downward thrust: The force exerted in the downward direction onto the drill bit. | E4: double | F4: force
A5: =IF(ISNA(VLOOKUP(B5,AssociatedElements!B$2:B2829,1,FALSE)),"Not used","") | B5: crowd_pressure | C5: Crowd pressure | D5: The pressure used to apply crowd force to the drill bit. | E5: double | F5: pressure
A6: =IF(ISNA(VLOOKUP(B6,AssociatedElements!B$2:B2838,1,FALSE)),"Not used","") | B6: depth | C6: Measured Depth | D6: The measured depth downhole reached by the drill bit; a positive number. | E6: double | F6: length
A7: =IF(ISNA(VLOOKUP(B7,AssociatedElements!B$2:B2861,1,FALSE)),"Not used","") | B7: drill_rod_weight | C7: Weight of drill rod or drill string | D7: Total weight of the drill rod or drill string; increases as a new section Is added. | E7: double | F7: force
A8: =IF(ISNA(VLOOKUP(B8,AssociatedElements!B$2:B2856,1,FALSE)),"Not used","") | B8: drillability_strength | C8: Drillability strength | D8: The inherent resistance of rock to drilling operations that takes into account various rock properties that affect drilling performance, such as: 1) rock hardness, 2) compressive strength, 3) abrasiveness, 4) fracture toughness and 5) mineral composition. Introduced by Karasawa and others, 2002. | E8: double | F8: pressure | G8: Karasawa, H., Ohno, T., Kosugi, M., and Rowley, J. C., 2002, “Methods to Estimate the Rock Strength and Tooth Wear While Drilling With Roller-Bits, Part 1: Milled-Tooth Bits,” ASME J. Energy Resour. Technol., 124, pp. 125–132. | H8: http://dx.doi.org/10.1115/1.1482405
A9: =IF(ISNA(VLOOKUP(B9,AssociatedElements!B$2:B2861,1,FALSE)),"Not used","") | B9: eccentric_rotation | C9: Eccentric rotation | D9: A logical flag; true when observation and/or rig vibration indicates significant offset between the bit axis of rotation and the wellbore center. | E9: boolean
A10: =IF(ISNA(VLOOKUP(B10,AssociatedElements!B$2:B2855,1,FALSE)),"Not used","") | B10: event_new_rod | C10: New rod event | D10: Set to true at the time or depth where a new rod is added to the drill string | E10: boolean
A11: =IF(ISNA(VLOOKUP(B11,AssociatedElements!B$2:B2861,1,FALSE)),"Not used","") | B11: exponent_method | C11: Exponent method | D11: A value to estimate pore pressure during drilling by calculating a "d-exponent," which is a normalized measure of drillability based on drilling parameters like weight on bit, rotary speed (RPM), and bit diameter, essentially indicating how easily a formation is being drilled through; this method was first described by Jorden and Shirley in 1966. | E11: double | G11: Jorden, J., and Shirley, O. 1966. “Application of Drilling Performance Data to Overpressure Detection.” Journal of Petroleum Technology, 7, 987–991. | H11: https://doi.org/10.2118/1407-PA
A12: =IF(ISNA(VLOOKUP(B12,AssociatedElements!B$2:B2829,1,FALSE)),"Not used","") | B12: fluid_injection_mass_rate | C12: Fluid injection mass flow rate | D12: Fluid injection mass flow rate: The mass of drilling fluid injected into the hole per unit time. | E12: double | F12: mass per time
A13: =IF(ISNA(VLOOKUP(B13,AssociatedElements!B$2:B2830,1,FALSE)),"Not used","") | B13: fluid_injection_pressure | C13: Fluid injection pressure | D13: Fluid injection pressure: The pressure at which drilling fluid is injected into the hole. | E13: double | F13: pressure
A14: =IF(ISNA(VLOOKUP(B14,AssociatedElements!B$2:B2828,1,FALSE)),"Not used","") | B14: fluid_injection_volume_rate | C14: Fluid injection volumetric flow rate, pumped inflow | D14: Fluid injection volumetric flow rate, pumped inflow: The volume of drilling fluid pumped into the well per unit time. | E14: double | F14: volume per time
A15: =IF(ISNA(VLOOKUP(B15,AssociatedElements!B$2:B2831,1,FALSE)),"Not used","") | B15: fluid_return_volume_rate | C15: Fluid return volumetric flow rate, returned outflow | D15: Fluid return volumetric flow rate, returned outflow: The volume of drilling fluid flowing back to the surface per unit time. | E15: double | F15: volume per time
A16: =IF(ISNA(VLOOKUP(B16,AssociatedElements!B$2:B2860,1,FALSE)),"Not used","") | B16: fluid_temperature | C16: Fluid temperature | D16: The temperature of the drilling fluid. | E16: double | F16: thermodynamic temperature
A17: =IF(ISNA(VLOOKUP(B17,AssociatedElements!B$2:B2843,1,FALSE)),"Not used","") | B17: gear_number | C17: Gear Number | D17: The number of the gear that is engaged. | E17: integer
A18: =IF(ISNA(VLOOKUP(B18,AssociatedElements!B$2:B2858,1,FALSE)),"Not used","") | B18: hammering_pressure | C18: Hammering pressure | D18: In percussive drilling, the pressure applied to the striking hammer | E18: double | F18: pressure
A19: =IF(ISNA(VLOOKUP(B19,AssociatedElements!B$2:B2860,1,FALSE)),"Not used","") | B19: hardness_parameter | C19: Hardness parameter | D19: Introduced by Bingham, 1965, this parameter characterizes material hardness through two complementary measures (Γhard and Γeasy) using drilling operational parameters like speed, force, bit size, penetration rate and torque. The two parameters are inversely related to each other. | E19: double | G19: Bingham, M. 1965. “A New Approach to Interpreting Rock Drillability.” Petroleum Publishing Company. | H19: https://books.google.com/books/about/A_New_Approach_to_Interpreting_Rock_Dril.html?id=8KcRnQEACAAJ
A20: =IF(ISNA(VLOOKUP(B20,AssociatedElements!B$2:B2857,1,FALSE)),"Not used","") | B20: holdback_pressure | C20: Holdback pressure | D20: Hydraulic pressure used to prevent the drilling rod from penetrating too fast, to prevent equipment from falling into a hole, or to compensate for the weight of rods added as the hole is drilled deeper. | E20: double | F20: pressure
A21: =IF(ISNA(VLOOKUP(B21,AssociatedElements!B$2:B2849,1,FALSE)),"Not used","") | B21: hydraulic_crowd_pressure | C21: Hydraulic crowd operating pressure | D21: Hydraulic crowd operating pressure: The pressure at which the hydraulic system operates to exert crowd force. | E21: double | F21: pressure
A22: =IF(ISNA(VLOOKUP(B22,AssociatedElements!B$2:B2841,1,FALSE)),"Not used","") | B22: hydraulic_fluid_flow_rate | C22: Hydraulic fluid flow rate | D22: Rate of flow of the rig hydraulic fluid. | E22: double | F22: volume per time
A23: =IF(ISNA(VLOOKUP(B23,AssociatedElements!B$2:B2848,1,FALSE)),"Not used","") | B23: hydraulic_torque_pressure | C23: Hydraulic torque operating pressure | D23: Hydraulic torque operating pressure. The pressure at which the hydraulic system operates to deliver torque. | E23: double | F23: pressure
A24: =IF(ISNA(VLOOKUP(B24,AssociatedElements!B$2:B2832,1,FALSE)),"Not used","") | B24: injected_fluid_density | C24: Injected fluid density | D24: Injected fluid density: The mass per unit volume of the injected fluid. | E24: double | F24: mass per volume
A25: =IF(ISNA(VLOOKUP(B25,AssociatedElements!B$2:B2833,1,FALSE)),"Not used","") | B25: injected_fluid_viscosity | C25: Injected fluid dynamic viscosity | D25: Injected fluid dynamic viscosity: The resistance of the injected fluid to flow. | E25: double | F25: dynamic viscosity
A26: =IF(ISNA(VLOOKUP(B26,AssociatedElements!B$2:B2856,1,FALSE)),"Not used","") | B26: net_crowd_pressure | C26: Net crowd pressure | D26: The difference between the crowd pressure and holdback pressure | E26: double | F26: pressure
A27: =IF(ISNA(VLOOKUP(B27,AssociatedElements!B$2:B2836,1,FALSE)),"Not used","") | B27: penetration_length | C27: Penetration length | D27: Penetration length: The length of a increment of the borehole advanced by the drill bit. | E27: double | F27: length
A28: =IF(ISNA(VLOOKUP(B28,AssociatedElements!B$2:B2863,1,FALSE)),"Not used","") | B28: penetration_per_revolution | C28: Penetration per revolution | D28: Penetration per revolution: the axial advance of the drill string or auger per full rotation of the drive - a feed-per-rotation efficiency indicator, distinct from penetration_rate (advance per unit time) and normally reported alongside rotational speed so the two can be cross-checked against each other. | E28: double | F28: length
A29: =IF(ISNA(VLOOKUP(B29,AssociatedElements!B$2:B2826,1,FALSE)),"Not used","") | B29: penetration_rate | C29: Penetration rate | D29: Penetration rate: The speed at which the drill bit penetrates the soil or rock. | E29: double | F29: length per time
A30: =IF(ISNA(VLOOKUP(B30,AssociatedElements!B$2:B2858,1,FALSE)),"Not used","") | B30: penetration_resistance | C30: Penetration resistance | D30: The amount of time it takes to drill a specified distance. Defined in ISO/IEC, 2016. | E30: double | F30: time per length | G30: ISO/IEC. 2016. Geotechnical Investigation and Testing – Field Testing – Part 15: Measuring While Drilling. ISO 22476-15:2016, International Standards Organization. Geneva, Switzerland. | H30: https://www.iso.org/standard/63412.html
A31: =IF(ISNA(VLOOKUP(B31,AssociatedElements!B$2:B2827,1,FALSE)),"Not used","") | B31: rotation_shaft | C31: Shaft rotational speed | D31: The number of revolutions per unit time measured on the shaft. | E31: double | F31: angular velocity
A32: =IF(ISNA(VLOOKUP(B32,AssociatedElements!B$2:B2828,1,FALSE)),"Not used","") | B32: rotation_tool | C32: Cutting tool rotational speed | D32: The number of revolutions per unit time measured on the drill bit or cutting tool. | E32: double | F32: angular velocity
A33: =IF(ISNA(VLOOKUP(B33,AssociatedElements!B$2:B2858,1,FALSE)),"Not used","") | B33: soil_rock_resistance | C33: Soil-Rock resistance | D33: The force or resistance encountered by drilling equipment as it penetrates through different layers of soil and rock formations, from ISO/IEC, 2016 | E33: double | F33: (mass per time) per area | G33: ISO/IEC. 2016. Geotechnical Investigation and Testing – Field Testing – Part 15: Measuring While Drilling. ISO 22476-15:2016, International Standards Organization. Geneva, Switzerland. | H33: https://www.iso.org/standard/63412.html
A34: =IF(ISNA(VLOOKUP(B34,AssociatedElements!B$2:B2857,1,FALSE)),"Not used","") | B34: somerton_index | C34: Somerton index | D34: From Somerton (1959), a strength parameter that correlates the effective weight on a bit, rotation rate, and advance rate. | E34: double | G34: Somerton W.H. 1959. “A laboratory study of rock breakage by rotary drilling.” J. Pet. Technol, 216 pp. 92-97. | H34: https://doi.org/10.2118/1163-G
A35: =IF(ISNA(VLOOKUP(B35,AssociatedElements!B$2:B2855,1,FALSE)),"Not used","") | B35: specific_energy | C35: Specific energy | D35: The amount of energy required to excavate a unit volume of soil or rock as defined by Teae, 1965 | E35: double | F35: pressure | G35: Teale, R. 1965. “The concept of specific energy in rock drilling.” International Journal of Rock Mechanics and Mining Sciences. 2(1): 57–73. | H35: https://doi.org/10.1016/0148-9062(65)90022-7
A36: =IF(ISNA(VLOOKUP(B36,AssociatedElements!B$2:B2862,1,FALSE)),"Not used","") | B36: stop_flag | C36: Stop Flag | D36: A logical flag; true when the drill rig advancement is stopped. | E36: boolean
A37: =IF(ISNA(VLOOKUP(B37,AssociatedElements!B$2:B2837,1,FALSE)),"Not used","") | B37: time | C37: Measured Time | D37: The time noted for a certain driling operation or when a measurement is obtained, measured as an elapsed time from the start of drilling increment. | E37: double | F37: time
A38: =IF(ISNA(VLOOKUP(B38,AssociatedElements!B$2:B2824,1,FALSE)),"Not used","") | B38: torque | C38: Torque | D38: Torque: The rotational force applied to the drill rod. | E38: double | F38: moment of force
A39: =IF(ISNA(VLOOKUP(B39,AssociatedElements!B$2:B2863,1,FALSE)),"Not used","") | B39: torque_tach | C39: Torque Tach | D39: The percentage of the maximum available torque being used by the drill rig. | E39: double | F39: dimensionless
A40: =IF(ISNA(VLOOKUP(B40,AssociatedElements!B$2:B2834,1,FALSE)),"Not used","") | B40: vibration_acceleration | C40: Vibration acceleration | D40: The rate of change of velocity per second of the drill string. | E40: double | F40: linear acceleration
...

Sheet AssociatedElements
A1: Start | B1: ID | C1: SourceElement | D1: ConditionalElement
A2: =IF(ISNA(VLOOKUP(B2,Definitions!B$2:B$1823,1,FALSE)),"Not listed","") | B2: alteration_index | C2: //diggs:propertyClass | D2: ancestor::diggs:measurement//diggs:procedure/diggs:MWDProcedure
A3: =IF(ISNA(VLOOKUP(B3,Definitions!B$2:B$1823,1,FALSE)),"Not listed","") | B3: calibration_flag | C3: //diggs:propertyClass | D3: ancestor::diggs:measurement//diggs:procedure/diggs:MWDProcedure
A4: =IF(ISNA(VLOOKUP(B4,Definitions!B$2:B$1823,1,FALSE)),"Not listed","") | B4: crowd_downward_thrust | C4: //diggs:propertyClass | D4: ancestor::diggs:measurement//diggs:procedure/diggs:MWDProcedure
A5: =IF(ISNA(VLOOKUP(B5,Definitions!B$2:B$1823,1,FALSE)),"Not listed","") | B5: crowd_pressure | C5: //diggs:propertyClass | D5: ancestor::diggs:measurement//diggs:procedure/diggs:MWDProcedure
A6: =IF(ISNA(VLOOKUP(B6,Definitions!B$2:B$1823,1,FALSE)),"Not listed","") | B6: depth | C6: //diggs:propertyClass | D6: ancestor::diggs:measurement//diggs:procedure/diggs:MWDProcedure
A7: =IF(ISNA(VLOOKUP(B7,Definitions!B$2:B$1823,1,FALSE)),"Not listed","") | B7: drill_rod_weight | C7: //diggs:propertyClass | D7: ancestor::diggs:measurement//diggs:procedure/diggs:MWDProcedure
A8: =IF(ISNA(VLOOKUP(B8,Definitions!B$2:B$1823,1,FALSE)),"Not listed","") | B8: drillability_strength | C8: //diggs:propertyClass | D8: ancestor::diggs:measurement//diggs:procedure/diggs:MWDProcedure
A9: =IF(ISNA(VLOOKUP(B9,Definitions!B$2:B$1823,1,FALSE)),"Not listed","") | B9: eccentric_rotation | C9: //diggs:propertyClass | D9: ancestor::diggs:measurement//diggs:procedure/diggs:MWDProcedure
A10: =IF(ISNA(VLOOKUP(B10,Definitions!B$2:B$1823,1,FALSE)),"Not listed","") | B10: event_new_rod | C10: //diggs:propertyClass | D10: ancestor::diggs:measurement//diggs:procedure/diggs:MWDProcedure
A11: =IF(ISNA(VLOOKUP(B11,Definitions!B$2:B$1823,1,FALSE)),"Not listed","") | B11: exponent_method | C11: //diggs:propertyClass | D11: ancestor::diggs:measurement//diggs:procedure/diggs:MWDProcedure
A12: =IF(ISNA(VLOOKUP(B12,Definitions!B$2:B$1823,1,FALSE)),"Not listed","") | B12: fluid_injection_mass_rate | C12: //diggs:propertyClass | D12: ancestor::diggs:measurement//diggs:procedure/diggs:MWDProcedure
A13: =IF(ISNA(VLOOKUP(B13,Definitions!B$2:B$1823,1,FALSE)),"Not listed","") | B13: fluid_injection_pressure | C13: //diggs:propertyClass | D13: ancestor::diggs:measurement//diggs:procedure/diggs:MWDProcedure
... A46: =IF(ISNA(VLOOKUP(B46,Definitions!B$2:B$1823,1,FALSE)),"Not listed","") | B46: rotation_tool | C46: //diggs:propertyClass | D46: ancestor::diggs:constructionActivity//diggs:RIInstallationRecord
A47: =IF(ISNA(VLOOKUP(#REF!,Definitions!B$2:B$1823,1,FALSE)),"Not listed","") | B47: crowd_downward_thrust | C47: //diggs:propertyClass | D47: ancestor::diggs:constructionActivity//diggs:RIInstallationRecord
A48: =IF(ISNA(VLOOKUP(#REF!,Definitions!B$2:B$1823,1,FALSE)),"Not listed","") | B48: crowd_pressure | C48: //diggs:propertyClass | D48: ancestor::diggs:constructionActivity//diggs:RIInstallationRecord
A49: =IF(ISNA(VLOOKUP(#REF!,Definitions!B$2:B$1823,1,FALSE)),"Not listed","") | B49: net_crowd_pressure | C49: //diggs:propertyClass | D49: ancestor::diggs:constructionActivity//diggs:RIInstallationRecord
B50: alteration_index | C50: //diggs:recordingParameter | D50: ancestor::diggs:ConstructionActivitySpecification
B51: calibration_flag | C51: //diggs:recordingParameter | D51: ancestor::diggs:ConstructionActivitySpecification
B52: crowd_downward_thrust | C52: //diggs:recordingParameter | D52: ancestor::diggs:ConstructionActivitySpecification
B53: crowd_pressure | C53: //diggs:recordingParameter | D53: ancestor::diggs:ConstructionActivitySpecification
B54: depth | C54: //diggs:recordingParameter | D54: ancestor::diggs:ConstructionActivitySpecification
B55: drill_rod_weight | C55: //diggs:recordingParameter | D55: ancestor::diggs:ConstructionActivitySpecification
B56: drillability_strength | C56: //diggs:recordingParameter | D56: ancestor::diggs:ConstructionActivitySpecification
B57: eccentric_rotation | C57: //diggs:recordingParameter | D57: ancestor::diggs:ConstructionActivitySpecification
B58: event_new_rod | C58: //diggs:recordingParameter | D58: ancestor::diggs:ConstructionActivitySpecification
B59: exponent_method | C59: //diggs:recordingParameter | D59: ancestor::diggs:ConstructionActivitySpecification
B60: fluid_injection_mass_rate | C60: //diggs:recordingParameter | D60: ancestor::diggs:ConstructionActivitySpecification
B61: fluid_injection_pressure | C61: //diggs:recordingParameter | D61: ancestor::diggs:ConstructionActivitySpecification
... B91: hydraulic_torque_pressure | C91: //diggs:propertyClass | D91: ancestor::diggs:constructionActivity//diggs:RIInstallationRecord

Sheet Lists
A1: DataType | B1: DataType2 | C1: QuantityClass
B2: anyURI | C2: absorbed dose
B3: base64binary | C3: activity of radioactivity
B4: boolean | C4: amount of substance
B5: byte | C5: amount of substance per amount of substance
B6: date | C6: amount of substance per area
B7: dateTime | C7: amount of substance per time
B8: decimal | C8: amount of substance per time per area
B9: double | C9: amount of substance per volume
B10: duration | C10: angle per length
B11: float | C11: angle per volume
B12: gDay | C12: angular acceleration
B13: gMonth | C13: angular velocity
... B17: hexBinary | C17: area
C18: area per amount of substance
B19: integer | C19: area per area
B20: language | C20: area per count
B21: long | C21: area per mass
B22: negativeInteger | C22: area per time
B23: nonNegativeInteger | C23: area per volume
B24: nonPositiveInteger | C24: attenuation per frequency interval
B25: normalizedString | C25: capacitance
B26: positiveInteger | C26: cation exchange capacity
B27: short | C27: data transfer speed
B28: string | C28: density or unit weight
C29: diffusion coefficient
B30: time | C30: diffusive time of flight
B31: token | C31: digital storage
B32: unsignedByte | C32: dimensionless
B33: unsignedInt | C33: dipole moment
B34: unsignedLong | C34: dose equivalent
B35: unsignedShort | C35: dynamic viscosity
B36: vector | C36: electric charge
C37: electric charge per area
C38: electric charge per mass
C39: electric charge per volume
C40: electric conductance
C41: electric conductivity
C42: electric current
C43: electric current density
...

Sheet Addtional Example
A1: Measured Depth (ft)
A2: RateOfPenetration (cm/min)
A3: RotationShaft(RPM)
A4: RotationTool(RPM)
A5: Flow (L/min)
A6: PressureFlush (bar)
A7: PressurePullDown(bar)
A8: RotationTach (RPM)
A9: TorqueTach(%)
A10: Gear(-)
A11: AugerOD (in)
A12: RockCoreSize(in)
... A15: Nvalue (-)
