Workbook

Sheet DictionaryName
A1: Start | B1: Dictionary ID | C1: DictionaryFile | D1: DictionaryName | E1: Description
E2: Leave this line blank
B3: propertyClass | C3: properties | D3: DIGGS Measurement Properties | E3: This dictionary contains the values for the propertyClass property of the diggs:Property object and the measurand property of the diggs:Detector object when used within the Test and Monitor DIGGS features. These values serve to define the ultimate results of geotechnical and environmental tests and monitoring activities that result from test procedures and monitoring sensors. The Xpaths to these occurrences are: 1) //diggs:Property/diggs:propertyClass (for Test, MaterialTest or Monitor) 2)//diggs:Detector/diggs:measurand (for measurand).

Sheet Definitions
A1: Start | B1: ID | C1: Name | D1: Description | E1: DataType | F1: QuantityClass | G1: Authority | H1: Reference | I1: SLD Comment | J1: SLD Changed | K1: ValueCodeSpace
A2: =IF(ISNA(VLOOKUP(B2,AssociatedElements!B$2:B623,1,FALSE)),"Not used","") | B2: a_pressure | C2: A-Pressure | D2: The gauge gas pressure against the inside of the membrane when the center of the membrane has lifted above its support and moved laterally 0.05-mm (tolerance +0.02, -0.00 mm) into the soil surrounding the blade. | E2: double | F2: pressure
A3: =IF(ISNA(VLOOKUP(B3,AssociatedElements!B$2:B624,1,FALSE)),"Not used","") | B3: aashto_group_index | C3: AASHTO Group Index | D3: The value of the AASHTO group index (GI) as defined by: GI= (F–35)[0.2+0.005(LL– 40)}+(F–15)(PI–10) where F is the percentage passing the 75 μm (0.075 mm) sieve, expressed as a whole number, LL is the liquid limit and PI is the plasticity index. | E3: string
A4: =IF(ISNA(VLOOKUP(B4,AssociatedElements!B$2:B625,1,FALSE)),"Not used","") | B4: aashto_symbol | C4: AASHTO Symbol | D4: The group or appropriate subgroup classification as defined by AASHTO M145-91 | E4: string
A5: =IF(ISNA(VLOOKUP(B5,AssociatedElements!B$2:B626,1,FALSE)),"Not used","") | B5: aggregate_abrasion_value | C5: Aggregate Abrasion Value | D5: A measure of the resistance of aggregate to surface wear by abrasion. | E5: double
A6: =IF(ISNA(VLOOKUP(B6,AssociatedElements!B$2:B627,1,FALSE)),"Not used","") | B6: aggregate_crushing_value | C6: Aggregate Crushing Value | D6: A relative measure of the resistance of an aggregate to crushing under a gradually applied compressive load. | E6: double
A7: =IF(ISNA(VLOOKUP(B7,AssociatedElements!B$2:B628,1,FALSE)),"Not used","") | B7: aggregate_elongation_index | C7: Aggregate Elongation Index | D7: The ratio, (by mass) of particles whose greatest dimension (length) is 1.8 times their mean dimension to the total mass of the sample. | E7: double
A8: =IF(ISNA(VLOOKUP(B8,AssociatedElements!B$2:B629,1,FALSE)),"Not used","") | B8: aggregate_flakiness_index | C8: Aggregate Flakiness Index | D8: Percentage (by mass) of aggregate particles whose least dimension is less than 0.6 times their mean size, to the total sample mass. | E8: double | F8: mass per mass | J8: x
A9: =IF(ISNA(VLOOKUP(B9,AssociatedElements!B$2:B630,1,FALSE)),"Not used","") | B9: aggregate_impact_value | C9: Aggregate Impact Value | D9: The resistance to impact of aggregates and is measured as the fraction of aggregates passing to the total mass of the sample. | E9: double | F9: mass per mass | J9: x
A10: =IF(ISNA(VLOOKUP(B10,AssociatedElements!B$2:B631,1,FALSE)),"Not used","") | B10: aggregate_LA_abrasion_loss | C10: Aggregate Los Angeles Abrasion Loss | D10: The actual measured loss (difference between the original mass and the final mass of the test sample), expressed as a percentage of the original mass of the test sample. | E10: double | F10: mass per mass | J10: x
A11: =IF(ISNA(VLOOKUP(B11,AssociatedElements!B$2:B632,1,FALSE)),"Not used","") | B11: aggregate_la_coefficient | C11: Aggregate Los Angeles Coefficient | D11: The loss (difference between the original weight and the final weight of the test sample), expressed as an integer. | E11: integer
A12: =IF(ISNA(VLOOKUP(B12,AssociatedElements!B$2:B633,1,FALSE)),"Not used","") | B12: aggregate_la_wear_ratio | C12: Aggregate Los Angeles Wear Ratio | D12: The actual measured loss (difference between the original mass and the final mass of the test sample), expressed as an integer ratio of the original mass of the test sample. | E12: integer
A13: =IF(ISNA(VLOOKUP(B13,AssociatedElements!B$2:B634,1,FALSE)),"Not used","") | B13: aggregate_polished_stone_value | C13: Aggregate Polished Stone Value | D13: A measure of the resistance of an aggregate to polishing. | E13: integer
A14: =IF(ISNA(VLOOKUP(B14,AssociatedElements!B$2:B635,1,FALSE)),"Not used","") | B14: aggregate_soundness_value | C14: Aggregate Soundness Value | D14: The amount of mass ost by degradation as determined by sieving and weighing the samples after the test cycles. | E14: double | F14: mass per mass | J14: x
A15: =IF(ISNA(VLOOKUP(B15,AssociatedElements!B$2:B636,1,FALSE)),"Not used","") | B15: aggregate_water_absorption | C15: Aggregate Water Absorption | D15: A water content value that gives an idea of strength of aggregate. Aggregates having more water absorption are more porous in nature and are generally considered unsuitable unless they are found to be acceptable based on strength, impact, and hardness tests. | E15: double | F15: mass per mass | J15: x
A16: =IF(ISNA(VLOOKUP(B16,AssociatedElements!B$2:B637,1,FALSE)),"Not used","") | B16: b_pressure | C16: B-Pressure | D16: The gauge gas pressure against the inside of the membrane when the center of the membrane has lifted above its support and moved laterally 1.10-mm (60.03 mm) into the soil surrounding the blade. | E16: double | F16: pressure
A17: =IF(ISNA(VLOOKUP(B17,AssociatedElements!B$2:B638,1,FALSE)),"Not used","") | B17: bleed | C17: Bleed | D17: The volume of clear water in a grout cylinder resulting from grout sedimentation, reported as a percentage of initial total column height. | E17: double | F17: length per length
A18: =IF(ISNA(VLOOKUP(B18,AssociatedElements!B$2:B639,1,FALSE)),"Not used","") | B18: blow_count | C18: Blow Count | D18: The number of blows of a hammer that drives a tool into the earth for a particular distance. The distance should correspond to the difference between the associated top and bottom positions recorded in the location property of the test, or be specified in the pen_increment property associated with a point location. | E18: integer | F18: dimensionless
A19: =IF(ISNA(VLOOKUP(B19,AssociatedElements!B$2:B640,1,FALSE)),"Not used","") | B19: bulk_density | C19: Density, Bulk (Natural) | D19: Total weight (of solids and water) divided by total volume of material, representing natural conditions. This is technically a unit weight not a density, but it is using the industry standard terminology assuming earth gravity. Value can also be reported in true density units (mass/volume) | E19: double | F19: force or mass per volume
A20: =IF(ISNA(VLOOKUP(B20,AssociatedElements!B$2:B641,1,FALSE)),"Not used","") | B20: c_pressure | C20: C-Pressure | D20: The gauge gas pressure against the inside of the membrane when the center of the membrane returns to the A-pressure position during a controlled, gradual deflation following the B-pressure. | E20: double | F20: pressure
A21: =IF(ISNA(VLOOKUP(B21,AssociatedElements!B$2:B642,1,FALSE)),"Not used","") | B21: cbr_0.1 | C21: Corrected Cbr At 0.100 in Penetration | D21: California Bearing Ratio is the ratio, expressed as a percentage, of the measured pressure for site soils at a penetration of 0.100 in divided by pressure to achieve equal penetration on a standard soil. | E21: double | F21: pressure per pressure
A22: =IF(ISNA(VLOOKUP(B22,AssociatedElements!B$2:B643,1,FALSE)),"Not used","") | B22: cbr_0.2 | C22: Corrected Cbr At 0.200 In Penetration | D22: California Bearing Ratio is the ratio, expressed as a percentage, of the measured pressure for site soils at a penetration of 0.200 in divided by pressure to achieve equal penetration on a standard soil. | E22: double | F22: pressure per pressure
A23: =IF(ISNA(VLOOKUP(B23,AssociatedElements!B$2:B644,1,FALSE)),"Not used","") | B23: chalk_crushing_value | C23: Chalk Crushing Value | D23: The Chalk Crushing Value is determined by using the chalk impact crushing test, which measures the rate at which a sample of chalk lumps crushes under impacts from a freefalling rammer. The chalk crushing value can be used, together with the saturation moisture content of the intact chalk lumps, to classify chalk in relation to its behavior as a freshly placed fill material. The test procedure is described for a single sample of chalk lumps, but normal procedure should be to calculate the mean value derived from six such tests on representative samples. | E23: double
A24: =IF(ISNA(VLOOKUP(B24,AssociatedElements!B$2:B645,1,FALSE)),"Not used","") | B24: chloride_content | C24: Chloride Content | D24: Chloride content of soil or groundwater by laboratory testing (corrosivity series). USE THIS ENTRY WHEN THE SOURCE DOES NOT STATE THE EXTRACTION BASIS - the case for the Jazera project record (GBL-24136), which reports a chloride content as a percentage without saying whether it is water- or acid-soluble. Where the basis IS known, prefer chloride_water_soluble or chloride_acid_soluble instead. | E24: double | F24: mass per mass
A25: =IF(ISNA(VLOOKUP(B25,AssociatedElements!B$2:B646,1,FALSE)),"Not used","") | B25: clay_percent_2_micron | C25: Clay Fraction < 2 Micron | D25: Represents the total amount of clay sized particles (<2 microns) in a test samples, expressed as a percentage by mass, to the total sample | E25: double | F25: mass per mass | J25: x
A26: =IF(ISNA(VLOOKUP(B26,AssociatedElements!B$2:B647,1,FALSE)),"Not used","") | B26: clay_percent_5_micron | C26: Clay Fraction < 5 Micron | D26: Represents the total amount of clay sized particles (<5 microns) in a test samples, expressed as a percentage by mass, to the total sample | E26: double | F26: mass per mass | J26: x
A27: =IF(ISNA(VLOOKUP(B27,AssociatedElements!B$2:B648,1,FALSE)),"Not used","") | B27: coef_consolidation_horiz | C27: Coefficient of Horizontal Consolidation (Ch) | D27: The horizontal coefficient of consolidation as derived from the dissipation test data from a cone penetration or dilatometer test. | E27: double | F27: area per time
A28: =IF(ISNA(VLOOKUP(B28,AssociatedElements!B$2:B649,1,FALSE)),"Not used","") | B28: coef_consolidation_vertical | C28: Coefficient of Vertical Consolidation(Cv) | D28: The vertical coefficient of consolidation as derived from a one-dimensional consolidation test in the lab. | E28: double | F28: area per time
A29: =IF(ISNA(VLOOKUP(B29,AssociatedElements!B$2:B650,1,FALSE)),"Not used","") | B29: coef_curvature | C29: Coefficient of Curvature | D29: A coefficient describing the degree of curvature of the grain size distribution. Defined as (d30)^2/((d60)*(d10)) | E29: double
A30: =IF(ISNA(VLOOKUP(B30,AssociatedElements!B$2:B651,1,FALSE)),"Not used","") | B30: coef_earth_pressure | C30: Coefficient of Earth Pressure, In Situ | D30: The ratio of horizontal earth pressure to vertical pressure for a sample in the field. | E30: double
A31: =IF(ISNA(VLOOKUP(B31,AssociatedElements!B$2:B652,1,FALSE)),"Not used","") | B31: coef_permeability | C31: Coefficient of Permeability | D31: The rate at which water flows through a soil is proportional to the hydraulic gradient and is expressed by Darcy's Law. Also known as the hydraulic conductivity. For lab tests, an average of measured values over several permeation trials. | E31: double | F31: length per time
A32: =IF(ISNA(VLOOKUP(B32,AssociatedElements!B$2:B653,1,FALSE)),"Not used","") | B32: coef_permeability_corrected | C32: Coefficient of Permeability, Corrected | D32: Coefficient of permeability, corrected to 20 degrees C. | E32: double | F32: length per time
A33: =IF(ISNA(VLOOKUP(B33,AssociatedElements!B$2:B654,1,FALSE)),"Not used","") | B33: coef_permeability_horiz | C33: Horizontal Coefficient of Permeability | D33: Coefficient of permeability, measuring rate of horizontal flow | E33: double | F33: length per time
A34: =IF(ISNA(VLOOKUP(B34,AssociatedElements!B$2:B655,1,FALSE)),"Not used","") | B34: coef_permeability_vert | C34: Vertical Coefficient of Permeability | D34: Coefficient of permeability, measuring rate of vertical flow | E34: double | F34: length per time
A35: =IF(ISNA(VLOOKUP(B35,AssociatedElements!B$2:B656,1,FALSE)),"Not used","") | B35: coef_uniformity | C35: Coefficient of Uniformity | D35: The ratio of D60/D10 | E35: double
A36: =IF(ISNA(VLOOKUP(B36,AssociatedElements!B$2:B657,1,FALSE)),"Not used","") | B36: cohesion_peak | C36: Peak Cohesion | D36: Shear resistance at zero normal stress ?the portion of the shear strength of a soil indicated by the term c, in Coulomb's equation | E36: double | F36: pressure
A37: =IF(ISNA(VLOOKUP(B37,AssociatedElements!B$2:B658,1,FALSE)),"Not used","") | B37: cohesion_residual | C37: Residual Cohesion | D37: Shear resistance at zero normal stress at the residual (or large deformation) strength. | E37: double | F37: pressure
A38: =IF(ISNA(VLOOKUP(B38,AssociatedElements!B$2:B659,1,FALSE)),"Not used","") | B38: colloid_percent | C38: Colloid Fraction | D38: represents the total amount of <1 micron size particles in a test sample, as a percentage of the total sample mass | E38: double | F38: mass per mass | J38: x
A39: =IF(ISNA(VLOOKUP(B39,AssociatedElements!B$2:B660,1,FALSE)),"Not used","") | B39: compression_index | C39: Compression Index | D39: Result from a Consolidation Test. This test is performed to determine the magnitude and rate of void ratio change for a laterally confined soil specimen that is subjected to different vertical pressures. From the measured data, the consolidation curve (pressure-void ratio relationship) can be plotted. This specific value is used for a specific portion of the log vertical pressure - void ratio curve to signify virgin compression. The one-dimension consolidation curve can be used to determine other values (e.g., the recompression index (slope of recompression curve) and the preconsolidation pressure (or maximum past pressure) of the soil). | E39: double
A40: =IF(ISNA(VLOOKUP(B40,AssociatedElements!B$2:B661,1,FALSE)),"Not used","") | B40: compressive_strength_unconfined | C40: Unconfined Compressive Strength | D40: Result of axial compression test using unconfined compression | E40: double | F40: pressure
...

Sheet AssociatedElements
A1: Start | B1: ID | C1: SourceElement | D1: ConditionalElement
A2: =IF(ISNA(VLOOKUP(B2,Definitions!B$2:B$1604,1,FALSE)),"Not listed","") | B2: a_pressure | C2: //diggs:propertyClass | D2: ancestor::diggs:measurement//diggs:procedure/diggs:FlatPlateDilatometerTest
A3: =IF(ISNA(VLOOKUP(B3,Definitions!B$2:B$1604,1,FALSE)),"Not listed","") | B3: aashto_group_index | C3: //diggs:propertyClass | D3: ancestor::diggs:measurement//diggs:procedure/diggs:ParticleSizeTest
A4: =IF(ISNA(VLOOKUP(B4,Definitions!B$2:B$1604,1,FALSE)),"Not listed","") | B4: aashto_symbol | C4: //diggs:propertyClass | D4: ancestor::diggs:measurement//diggs:procedure/diggs:ParticleSizeTest
A5: =IF(ISNA(VLOOKUP(B5,Definitions!B$2:B$1604,1,FALSE)),"Not listed","") | B5: aggregate_abrasion_value | C5: //diggs:propertyClass | D5: ancestor::diggs:measurement//diggs:procedure/diggs:AggregateAbrasionValueTest
A6: =IF(ISNA(VLOOKUP(B6,Definitions!B$2:B$1604,1,FALSE)),"Not listed","") | B6: aggregate_crushing_value | C6: //diggs:propertyClass | D6: ancestor::diggs:measurement//diggs:procedure/diggs:AggregateCrushingValueTest
A7: =IF(ISNA(VLOOKUP(B7,Definitions!B$2:B$1604,1,FALSE)),"Not listed","") | B7: aggregate_elongation_index | C7: //diggs:propertyClass | D7: ancestor::diggs:measurement//diggs:procedure/diggs:AggregateElongationIndexTest
A8: =IF(ISNA(VLOOKUP(B8,Definitions!B$2:B$1604,1,FALSE)),"Not listed","") | B8: aggregate_flakiness_index | C8: //diggs:propertyClass | D8: ancestor::diggs:measurement//diggs:procedure/diggs:AggregateFlakinessIndexTest
A9: =IF(ISNA(VLOOKUP(B9,Definitions!B$2:B$1604,1,FALSE)),"Not listed","") | B9: aggregate_impact_value | C9: //diggs:propertyClass | D9: ancestor::diggs:measurement//diggs:procedure/diggs:AggregateImpactValueTest
A10: =IF(ISNA(VLOOKUP(B10,Definitions!B$2:B$1604,1,FALSE)),"Not listed","") | B10: aggregate_LA_abrasion_loss | C10: //diggs:propertyClass | D10: ancestor::diggs:measurement//diggs:procedure/diggs:LosAngelesAbrasionTest
A11: =IF(ISNA(VLOOKUP(B11,Definitions!B$2:B$1604,1,FALSE)),"Not listed","") | B11: aggregate_la_coefficient | C11: //diggs:propertyClass | D11: ancestor::diggs:measurement//diggs:procedure/diggs:LosAngelesAbrasionTest
A12: =IF(ISNA(VLOOKUP(B12,Definitions!B$2:B$1604,1,FALSE)),"Not listed","") | B12: aggregate_la_wear_ratio | C12: //diggs:propertyClass | D12: ancestor::diggs:measurement//diggs:procedure/diggs:LosAngelesAbrasionTest
A13: =IF(ISNA(VLOOKUP(B13,Definitions!B$2:B$1604,1,FALSE)),"Not listed","") | B13: aggregate_polished_stone_value | C13: //diggs:propertyClass | D13: ancestor::diggs:measurement//diggs:procedure/diggs:AggregatePolishedStoneValueTest
... A22: =IF(ISNA(VLOOKUP(B22,Definitions!B$2:B$1604,1,FALSE)),"Not listed","") | B22: bulk_density | C22: //diggs:propertyClass | D22: ancestor::diggs:measurement//diggs:procedure/diggs:LabDensityTest
A23: =IF(ISNA(VLOOKUP([1]AssociatedElements!B279,Definitions!B$2:B$1604,1,FALSE)),"Not listed","") | B23: bulk_density_true | C23: //diggs:propertyClass | D23: ancestor::diggs:measurement//diggs:procedure/diggs:InsituCBRTest
A24: =IF(ISNA(VLOOKUP([1]AssociatedElements!B280,Definitions!B$2:B$1604,1,FALSE)),"Not listed","") | B24: bulk_density_true | C24: //diggs:propertyClass | D24: ancestor::diggs:measurement//diggs:procedure/diggs:InsituDensityTest
A25: =IF(ISNA(VLOOKUP([1]AssociatedElements!B281,Definitions!B$2:B$1604,1,FALSE)),"Not listed","") | B25: bulk_density_true | C25: //diggs:propertyClass | D25: ancestor::diggs:measurement//diggs:procedure/diggs:LabCBRTest
A26: =IF(ISNA(VLOOKUP([1]AssociatedElements!B282,Definitions!B$2:B$1604,1,FALSE)),"Not listed","") | B26: bulk_density_true | C26: //diggs:propertyClass | D26: ancestor::diggs:measurement//diggs:procedure/diggs:LabDensityTest
A27: =IF(ISNA(VLOOKUP(B27,Definitions!B$2:B$1604,1,FALSE)),"Not listed","") | B27: c_pressure | C27: //diggs:propertyClass | D27: ancestor::diggs:measurement//diggs:procedure/diggs:FlatPlateDilatometerTest
A28: =IF(ISNA(VLOOKUP([1]AssociatedElements!B289,Definitions!B$2:B$1604,1,FALSE)),"Not listed","") | B28: c_value | C28: //diggs:propertyClass | D28: ancestor::diggs:measurement//diggs:procedure/diggs:LabCompactionTest
A29: =IF(ISNA(VLOOKUP(B29,Definitions!B$2:B$1604,1,FALSE)),"Not listed","") | B29: cbr_0.1 | C29: //diggs:propertyClass | D29: ancestor::diggs:measurement//diggs:procedure/diggs:InsituCBRTest
A30: =IF(ISNA(VLOOKUP(B30,Definitions!B$2:B$1604,1,FALSE)),"Not listed","") | B30: cbr_0.1 | C30: //diggs:propertyClass | D30: ancestor::diggs:measurement//diggs:procedure/diggs:LabCBRTest
A31: =IF(ISNA(VLOOKUP(B31,Definitions!B$2:B$1604,1,FALSE)),"Not listed","") | B31: cbr_0.2 | C31: //diggs:propertyClass | D31: ancestor::diggs:measurement//diggs:procedure/diggs:InsituCBRTest
A32: =IF(ISNA(VLOOKUP(B32,Definitions!B$2:B$1604,1,FALSE)),"Not listed","") | B32: cbr_0.2 | C32: //diggs:propertyClass | D32: ancestor::diggs:measurement//diggs:procedure/diggs:LabCBRTest
A33: =IF(ISNA(VLOOKUP(B33,Definitions!B$2:B$1604,1,FALSE)),"Not listed","") | B33: chalk_crushing_value | C33: //diggs:propertyClass | D33: ancestor::diggs:measurement//diggs:procedure/diggs:ChalkCrushingValueTest
A34: =IF(ISNA(VLOOKUP(B34,Definitions!B$2:B$1604,1,FALSE)),"Not listed","") | B34: chloride_content | C34: //diggs:propertyClass | D34: ancestor::diggs:measurement//diggs:procedure/diggs:LabChemicalTest
A35: =IF(ISNA(VLOOKUP(B35,Definitions!B$2:B$1604,1,FALSE)),"Not listed","") | B35: clay_percent_2_micron | C35: //diggs:propertyClass | D35: ancestor::diggs:measurement//diggs:procedure/diggs:ParticleSizeTest
A36: =IF(ISNA(VLOOKUP(B36,Definitions!B$2:B$1604,1,FALSE)),"Not listed","") | B36: clay_percent_5_micron | C36: //diggs:propertyClass | D36: ancestor::diggs:measurement//diggs:procedure/diggs:ParticleSizeTest
A37: =IF(ISNA(VLOOKUP(B37,Definitions!B$2:B$1604,1,FALSE)),"Not listed","") | B37: coef_consolidation_horiz | C37: //diggs:propertyClass | D37: ancestor::diggs:measurement//diggs:procedure/diggs:FlatPlateDilatometerTest
A38: =IF(ISNA(VLOOKUP(B38,Definitions!B$2:B$1604,1,FALSE)),"Not listed","") | B38: coef_consolidation_horiz | C38: //diggs:propertyClass | D38: ancestor::diggs:measurement//diggs:procedure/diggs:PorePressureDissipationTest
A39: =IF(ISNA(VLOOKUP(B39,Definitions!B$2:B$1604,1,FALSE)),"Not listed","") | B39: coef_consolidation_vertical | C39: //diggs:propertyClass | D39: ancestor::diggs:measurement//diggs:procedure/diggs:ConsolidationTest
A40: =IF(ISNA(VLOOKUP(B40,Definitions!B$2:B$1604,1,FALSE)),"Not listed","") | B40: coef_curvature | C40: //diggs:propertyClass | D40: ancestor::diggs:measurement//diggs:procedure/diggs:MaterialGradationTest
... A61: =IF(ISNA(VLOOKUP(B61,Definitions!B$2:B$1604,1,FALSE)),"Not listed","") | B61: cohesion_peak | C61: //diggs:propertyClass | D61: ancestor::diggs:measurement//diggs:procedure/diggs:TriaxialTest
A62: =IF(ISNA(VLOOKUP(B61,Definitions!B$2:B$1604,1,FALSE)),"Not listed","") | B62: cohesion_residual | C62: //diggs:propertyClass | D62: ancestor::diggs:measurement//diggs:procedure/diggs:DirectShearTest
A63: =IF(ISNA(VLOOKUP(B62,Definitions!B$2:B$1604,1,FALSE)),"Not listed","") | B63: cohesion_residual | C63: //diggs:propertyClass | D63: ancestor::diggs:measurement//diggs:procedure/diggs:TriaxialTest
A64: =IF(ISNA(VLOOKUP(B62,Definitions!B$2:B$1604,1,FALSE)),"Not listed","") | B64: colloid_percent | C64: //diggs:propertyClass | D64: ancestor::diggs:measurement//diggs:procedure/diggs:ParticleSizeTest
A65: =IF(ISNA(VLOOKUP(B63,Definitions!B$2:B$1604,1,FALSE)),"Not listed","") | B65: compression_index | C65: //diggs:propertyClass | D65: ancestor::diggs:measurement//diggs:procedure/diggs:ConsolidationTest
A66: =IF(ISNA(VLOOKUP(B64,Definitions!B$2:B$1604,1,FALSE)),"Not listed","") | B66: compressive_strength_unconfined | C66: //diggs:propertyClass | D66: ancestor::diggs:measurement//diggs:procedure/diggs:InSituPenetrometerTest
A67: =IF(ISNA(VLOOKUP(B65,Definitions!B$2:B$1604,1,FALSE)),"Not listed","") | B67: compressive_strength_unconfined | C67: //diggs:propertyClass | D67: ancestor::diggs:measurement//diggs:procedure/diggs:LabPenetrometerTest
A68: =IF(ISNA(VLOOKUP(B66,Definitions!B$2:B$1604,1,FALSE)),"Not listed","") | B68: compressive_strength_unconfined | C68: //diggs:propertyClass | D68: ancestor::diggs:measurement//diggs:procedure/diggs:PocketPenetrometerTest
...

Sheet ValueBindings
A1: Start | B1: ID | C1: SubjectElement | D1: Method | E1: RealizedValueXpath | F1: ReferenceValueXpath | G1: ReferenceSource | H1: ReferenceEvaluation | I1: NormalizeByXpath
B2: compressive_strength_unconfined | D2: direct | E2: for $r in $evidence/descendant-or-self::*[diggs:results//diggs:propertyClass/@codeSpace[ends-with(., '#compressive_strength_unconfined')]] return diggs:series($r, 'compressive_strength_unconfined') ! ?2
B3: slump | D3: direct | E3: for $r in $evidence/descendant-or-self::*[diggs:results//diggs:propertyClass/@codeSpace[ends-with(., '#slump')]] return diggs:series($r, 'slump') ! ?2
B4: modulus_youngs | D4: direct | E4: for $r in $evidence/descendant-or-self::*[diggs:results//diggs:propertyClass/@codeSpace[ends-with(., '#modulus_youngs')]] return diggs:series($r, 'modulus_youngs') ! ?2
B5: settlement | C5: diggs:LoadTransferPlatform | D5: value at | E5: let $r := $evidence/diggs:outcome/*[1], $x := diggs:series($r, 'applied_stress'), $y := diggs:series($r, 'settlement'), $p := diggs:series($r, 'loading_phase') return for $i in 1 to count($y) return if ($p[$i]?2 = 'loading') then [$x[$i]?2, $y[$i]?2] else ()
B6: settlement | D6: direct | E6: for $r in $evidence/descendant-or-self::*[diggs:results//diggs:propertyClass/@codeSpace[ends-with(., '#settlement')]] return diggs:series($r, 'settlement') ! ?2
B7: toe_depth_deviation | C7: diggs:Test | D7: direct | E7: let $t := diggs:otherMeasurementProperty/diggs:AuthorizedParameter[diggs:parameterName/@codeSpace[ends-with(., '#toe_depth')]]/diggs:parameterValue, $l := diggs:procedure/*/diggs:referenceLength return if (exists($t) and exists($l)) then abs(number($t) - number($l)) * 100 div number($l) else ()
B8: relative_reflection_amplitude | C8: diggs:Test | D8: direct | E8: diggs:otherMeasurementProperty/diggs:AuthorizedParameter[diggs:parameterName/@codeSpace[ends-with(., '#relative_reflection_amplitude')]]/diggs:parameterValue
B9: relative_toe_amplitude | C9: diggs:Test | D9: direct | E9: diggs:otherMeasurementProperty/diggs:AuthorizedParameter[diggs:parameterName/@codeSpace[ends-with(., '#relative_toe_amplitude')]]/diggs:parameterValue

Sheet Lists
A1: DataType | B1: DataType2 | C1: QuantityClass | D1: Column2
B2: anyURI | C2: absorbed dose | E2: =VLOOKUP(C2,J$2:J$300,1,FALSE) | F2: =SUBSTITUTE(PROPER(LOWER(C2))," ","") | J2: (amount of substance per time) per area
B3: base64binary | C3: activity [of radioactivity] | E3: =VLOOKUP(C3,J$2:J$300,1,FALSE) | F3: =SUBSTITUTE(PROPER(LOWER(C3))," ","") | J3: (energy per mass) per time
B4: boolean | C4: amount of substance | E4: =VLOOKUP(C4,J$2:J$300,1,FALSE) | F4: =SUBSTITUTE(PROPER(LOWER(C4))," ","") | J4: (mass per time) per area
B5: byte | C5: amount of substance per amount of substance | E5: =VLOOKUP(C5,J$2:J$300,1,FALSE) | F5: =SUBSTITUTE(PROPER(LOWER(C5))," ","") | J5: (mass per time) per length
B6: date | C6: amount of substance per area | E6: =VLOOKUP(C6,J$2:J$300,1,FALSE) | F6: =SUBSTITUTE(PROPER(LOWER(C6))," ","") | J6: (mass per volume) per length
B7: dateTime | C7: amount of substance per mass | D7: use for cation exchange capacity | E7: =VLOOKUP(C7,J$2:J$300,1,FALSE) | F7: =SUBSTITUTE(PROPER(LOWER(C7))," ","") | J7: (volume per time) length
B8: decimal | C8: amount of substance per time | E8: =VLOOKUP(C8,J$2:J$300,1,FALSE) | F8: =SUBSTITUTE(PROPER(LOWER(C8))," ","") | J8: (volume per time) per (pressure length)
B9: double | C9: (amount of substance per time) per area | E9: =VLOOKUP(C9,J$2:J$300,1,FALSE) | F9: =SUBSTITUTE(PROPER(LOWER(C9))," ","") | J9: (volume per time) per area
B10: duration | C10: amount of substance per volume | E10: =VLOOKUP(C10,J$2:J$300,1,FALSE) | F10: =SUBSTITUTE(PROPER(LOWER(C10))," ","") | J10: (volume per time) per length
B11: float | C11: angle per length | E11: =VLOOKUP(C11,J$2:J$300,1,FALSE) | F11: =SUBSTITUTE(PROPER(LOWER(C11))," ","") | J11: (volume per time) per pressure
B12: gDay | C12: angle per volume | E12: =VLOOKUP(C12,J$2:J$300,1,FALSE) | F12: =SUBSTITUTE(PROPER(LOWER(C12))," ","") | J12: (volume per time) per time
B13: gMonth | C13: angular acceleration | E13: =VLOOKUP(C13,J$2:J$300,1,FALSE) | F13: =SUBSTITUTE(PROPER(LOWER(C13))," ","") | J13: (volume per time) per volume
B14: gMonthDay | C14: angular velocity | E14: =VLOOKUP(C14,J$2:J$300,1,FALSE) | F14: =SUBSTITUTE(PROPER(LOWER(C14))," ","") | J14: API gamma ray
B15: gYear | C15: api gamma ray | E15: =VLOOKUP(C15,J$2:J$300,1,FALSE) | F15: =SUBSTITUTE(PROPER(LOWER(C15))," ","") | J15: API gravity
B16: gYearMonth | C16: api gravity | E16: =VLOOKUP(C16,J$2:J$300,1,FALSE) | F16: =SUBSTITUTE(PROPER(LOWER(C16))," ","") | J16: API neutron
B17: hexBinary | C17: api neutron | E17: =VLOOKUP(C17,J$2:J$300,1,FALSE) | F17: =SUBSTITUTE(PROPER(LOWER(C17))," ","") | J17: absorbed dose
B18: integer | C18: area | E18: =VLOOKUP(C18,J$2:J$300,1,FALSE) | F18: =SUBSTITUTE(PROPER(LOWER(C18))," ","") | J18: activity [of radioactivity]
B19: language | C19: area per amount of substance | E19: =VLOOKUP(C19,J$2:J$300,1,FALSE) | F19: =SUBSTITUTE(PROPER(LOWER(C19))," ","") | J19: amount of substance
B20: long | C20: area per area | E20: =VLOOKUP(C20,J$2:J$300,1,FALSE) | F20: =SUBSTITUTE(PROPER(LOWER(C20))," ","") | J20: amount of substance per amount of substance
B21: negativeInteger | C21: area per count | D21: In EML schema but not in EML dictionary | E21: =VLOOKUP(C21,J$2:J$300,1,FALSE) | F21: =SUBSTITUTE(PROPER(LOWER(C21))," ","") | J21: amount of substance per area
B22: nonNegativeInteger | C22: area per mass | E22: =VLOOKUP(C22,J$2:J$300,1,FALSE) | F22: =SUBSTITUTE(PROPER(LOWER(C22))," ","") | J22: amount of substance per time
B23: nonPositiveInteger | C23: area per time | E23: =VLOOKUP(C23,J$2:J$300,1,FALSE) | F23: =SUBSTITUTE(PROPER(LOWER(C23))," ","") | J23: amount of substance per volume
B24: normalizedString | C24: area per volume | E24: =VLOOKUP(C24,J$2:J$300,1,FALSE) | F24: =SUBSTITUTE(PROPER(LOWER(C24))," ","") | J24: angle per length
B25: positiveInteger | C25: attenuation per frequency interval | E25: =VLOOKUP(C25,J$2:J$300,1,FALSE) | F25: =SUBSTITUTE(PROPER(LOWER(C25))," ","") | J25: angle per volume
B26: short | C26: capacitance | E26: =VLOOKUP(C26,J$2:J$300,1,FALSE) | F26: =SUBSTITUTE(PROPER(LOWER(C26))," ","") | J26: angular acceleration
B27: string | C27: data transfer speed | E27: =VLOOKUP(C27,J$2:J$300,1,FALSE) | F27: =SUBSTITUTE(PROPER(LOWER(C27))," ","") | J27: angular velocity
B28: string | C28: diffusion coefficient | E28: =VLOOKUP(C28,J$2:J$300,1,FALSE) | F28: =SUBSTITUTE(PROPER(LOWER(C28))," ","") | J28: area
B29: time | C29: diffusive time of flight | D29: In EML schema but not in EML dictionary | E29: =VLOOKUP(C29,J$2:J$300,1,FALSE) | F29: =SUBSTITUTE(PROPER(LOWER(C29))," ","") | J29: area per amount of substance
B30: token | C30: digital storage | E30: =VLOOKUP(C30,J$2:J$300,1,FALSE) | F30: =SUBSTITUTE(PROPER(LOWER(C30))," ","") | J30: area per area
B31: unsignedByte | C31: dimensionless | E31: =VLOOKUP(C31,J$2:J$300,1,FALSE) | F31: =SUBSTITUTE(PROPER(LOWER(C31))," ","") | J31: area per mass
B32: unsignedInt | C32: dipole moment | E32: =VLOOKUP(C32,J$2:J$300,1,FALSE) | F32: =SUBSTITUTE(PROPER(LOWER(C32))," ","") | J32: area per time
B33: unsignedLong | C33: dose equivalent | E33: =VLOOKUP(C33,J$2:J$300,1,FALSE) | F33: =SUBSTITUTE(PROPER(LOWER(C33))," ","") | J33: area per volume
B34: unsignedShort | C34: dynamic viscosity | E34: =VLOOKUP(C34,J$2:J$300,1,FALSE) | F34: =SUBSTITUTE(PROPER(LOWER(C34))," ","") | J34: attenuation per frequency interval
B35: vector | C35: electric charge | E35: =VLOOKUP(C35,J$2:J$300,1,FALSE) | F35: =SUBSTITUTE(PROPER(LOWER(C35))," ","") | J35: capacitance
C36: electric charge per area | E36: =VLOOKUP(C36,J$2:J$300,1,FALSE) | F36: =SUBSTITUTE(PROPER(LOWER(C36))," ","") | J36: data transfer speed
C37: electric charge per mass | E37: =VLOOKUP(C37,J$2:J$300,1,FALSE) | F37: =SUBSTITUTE(PROPER(LOWER(C37))," ","") | J37: diffusion coefficient
C38: electric charge per volume | E38: =VLOOKUP(C38,J$2:J$300,1,FALSE) | F38: =SUBSTITUTE(PROPER(LOWER(C38))," ","") | J38: digital storage
C39: electric conductance | E39: =VLOOKUP(C39,J$2:J$300,1,FALSE) | F39: =SUBSTITUTE(PROPER(LOWER(C39))," ","") | J39: dimensionless
C40: electric conductivity | E40: =VLOOKUP(C40,J$2:J$300,1,FALSE) | F40: =SUBSTITUTE(PROPER(LOWER(C40))," ","") | J40: dipole moment
...
