Workbook

Sheet DictionaryName
A1: Start | B1: Dictionary ID | C1: DictionaryFile | D1: DictionaryName | E1: Description
E2: Leave this line blank
B3: referentName | C3: referentName | D3: DIGGS Referent Name Codelist Definitions | E3: Names of referents - the reference points from which distance along a linear feature (a borehole, well, pile, column, core or survey line) is measured - used for the value of the name property of diggs:Referent. The value may be the entry's name or any of its listed abbreviations; identify the entry in codeSpace, which also resolves an abbreviation that two entries share (TOC, BOC, TOR). The entries cover the standard values of diggs:ReferentTypeEnum, the referentType of the same Referent, and further referents common in geotechnical practice. Provisional pending SME review.

Sheet Definitions
A1: Start | B1: ID | C1: Name | D1: Description | E1: DataType | F1: QuantityClass | G1: Authority | H1: Reference | I1: ValueCodeSpace
A2: =IF(ISNA(VLOOKUP(B2,AssociatedElements!B$2:B2940,1,FALSE)),"Not used","") | B2: ground_surface | C2: Ground surface | D2: The ground surface at the location at the time of the work. | E2: string | G2: DIGGS
A3: =IF(ISNA(VLOOKUP(B3,AssociatedElements!B$2:B2940,1,FALSE)),"Not used","") | B3: original_ground_surface | C3: Original ground surface | D3: The natural ground surface before any cut, fill or platform construction, where it differs from the ground surface at the time of the work. | E3: string | G3: DIGGS
A4: =IF(ISNA(VLOOKUP(B4,AssociatedElements!B$2:B2940,1,FALSE)),"Not used","") | B4: finished_grade | C4: Finished grade | D4: The final ground surface after earthworks, as designed or as constructed. | E4: string | G4: DIGGS
A5: =IF(ISNA(VLOOKUP(B5,AssociatedElements!B$2:B2940,1,FALSE)),"Not used","") | B5: working_platform | C5: Top of working platform | D5: The surface of a temporary working or piling platform from which drilling, piling or ground improvement is carried out. | E5: string | G5: DIGGS
A6: =IF(ISNA(VLOOKUP(B6,AssociatedElements!B$2:B2940,1,FALSE)),"Not used","") | B6: top_of_load_transfer_platform | C6: Top of load transfer platform | D6: The top of the granular load transfer platform placed over rigid inclusions. | E6: string | G6: DIGGS
A7: =IF(ISNA(VLOOKUP(B7,AssociatedElements!B$2:B2940,1,FALSE)),"Not used","") | B7: bottom_of_excavation | C7: Bottom of excavation | D7: The base of an excavation from which a hole, pile or measurement starts. | E7: string | G7: DIGGS
A8: =IF(ISNA(VLOOKUP(B8,AssociatedElements!B$2:B2940,1,FALSE)),"Not used","") | B8: water_surface | C8: Water surface | D8: The water surface at the time of the work, for a hole advanced or a measurement made over water. | E8: string | G8: DIGGS
A9: =IF(ISNA(VLOOKUP(B9,AssociatedElements!B$2:B2940,1,FALSE)),"Not used","") | B9: sea_floor | C9: Sea floor | D9: The bed of the sea, lake or river at the location. | E9: string | G9: DIGGS
A10: =IF(ISNA(VLOOKUP(B10,AssociatedElements!B$2:B2940,1,FALSE)),"Not used","") | B10: mudline | C10: Mudline | D10: The sea or river bed as used in offshore and marine foundation practice. | E10: string | G10: DIGGS
A11: =IF(ISNA(VLOOKUP(B11,AssociatedElements!B$2:B2940,1,FALSE)),"Not used","") | B11: kelly_bushing | C11: Kelly bushing | D11: The top of the kelly bushing on the drilling rig floor; a common depth datum in rotary drilling. | E11: string | G11: DIGGS
A12: =IF(ISNA(VLOOKUP(B12,AssociatedElements!B$2:B2940,1,FALSE)),"Not used","") | B12: rotary_bushing | C12: Rotary bushing | D12: The top of the rotary bushing on the drilling rig floor. | E12: string | G12: DIGGS
A13: =IF(ISNA(VLOOKUP(B13,AssociatedElements!B$2:B2940,1,FALSE)),"Not used","") | B13: rotary_table | C13: Rotary table | D13: The top of the rotary table on the drilling rig floor. | E13: string | G13: DIGGS
A14: =IF(ISNA(VLOOKUP(B14,AssociatedElements!B$2:B2940,1,FALSE)),"Not used","") | B14: derrick_floor | C14: Derrick floor | D14: The working floor of the drilling rig. | E14: string | G14: DIGGS
A15: =IF(ISNA(VLOOKUP(B15,AssociatedElements!B$2:B2940,1,FALSE)),"Not used","") | B15: crown_valve | C15: Crown valve | D15: The crown (swab) valve at the top of a wellhead assembly. | E15: string | G15: DIGGS
A16: =IF(ISNA(VLOOKUP(B16,AssociatedElements!B$2:B2940,1,FALSE)),"Not used","") | B16: casing_flange | C16: Casing flange | D16: The flange at the top of a casing string or wellhead. | E16: string | G16: DIGGS
A17: =IF(ISNA(VLOOKUP(B17,AssociatedElements!B$2:B2940,1,FALSE)),"Not used","") | B17: top_of_hole | C17: Top of hole | D17: The point at which the hole enters the ground or rock (the collar). | E17: string | G17: DIGGS
A18: =IF(ISNA(VLOOKUP(B18,AssociatedElements!B$2:B2940,1,FALSE)),"Not used","") | B18: bottom_of_hole | C18: Bottom of hole | D18: The deepest point reached by the hole. | E18: string | G18: DIGGS
A19: =IF(ISNA(VLOOKUP(B19,AssociatedElements!B$2:B2940,1,FALSE)),"Not used","") | B19: top_of_casing | C19: Top of casing | D19: The top of the casing installed in the hole, including an inclinometer or well casing. | E19: string | G19: DIGGS
A20: =IF(ISNA(VLOOKUP(B20,AssociatedElements!B$2:B2940,1,FALSE)),"Not used","") | B20: bottom_of_casing | C20: Bottom of casing | D20: The bottom (shoe) of the casing installed in the hole. | E20: string | G20: DIGGS
A21: =IF(ISNA(VLOOKUP(B21,AssociatedElements!B$2:B2940,1,FALSE)),"Not used","") | B21: top_of_riser | C21: Top of riser | D21: The top of the riser pipe of a monitoring well or piezometer. | E21: string | G21: DIGGS
A22: =IF(ISNA(VLOOKUP(B22,AssociatedElements!B$2:B2940,1,FALSE)),"Not used","") | B22: top_of_protective_casing | C22: Top of protective casing | D22: The top of the outer protective casing (stickup or monument) around a well or instrument. | E22: string | G22: DIGGS
A23: =IF(ISNA(VLOOKUP(B23,AssociatedElements!B$2:B2940,1,FALSE)),"Not used","") | B23: measuring_point | C23: Measuring point | D23: The marked point from which water levels or other readings in a well, piezometer or instrument are measured. | E23: string | G23: DIGGS
A24: =IF(ISNA(VLOOKUP(B24,AssociatedElements!B$2:B2940,1,FALSE)),"Not used","") | B24: kickoff_point | C24: Kickoff point | D24: The point at which a directional hole departs from its initial trajectory. | E24: string | G24: DIGGS
A25: =IF(ISNA(VLOOKUP(B25,AssociatedElements!B$2:B2940,1,FALSE)),"Not used","") | B25: top_of_core | C25: Top of core | D25: The top of a core run or core piece. | E25: string | G25: DIGGS
A26: =IF(ISNA(VLOOKUP(B26,AssociatedElements!B$2:B2940,1,FALSE)),"Not used","") | B26: bottom_of_core | C26: Bottom of core | D26: The bottom of a core run or core piece. | E26: string | G26: DIGGS
A27: =IF(ISNA(VLOOKUP(B27,AssociatedElements!B$2:B2940,1,FALSE)),"Not used","") | B27: top_of_sample | C27: Top of sample | D27: The top of a sample or sample tube, from which positions within the sample are measured. | E27: string | G27: DIGGS
A28: =IF(ISNA(VLOOKUP(B28,AssociatedElements!B$2:B2940,1,FALSE)),"Not used","") | B28: bottom_of_sample | C28: Bottom of sample | D28: The bottom of a sample or sample tube. | E28: string | G28: DIGGS
A29: =IF(ISNA(VLOOKUP(B29,AssociatedElements!B$2:B2940,1,FALSE)),"Not used","") | B29: pile_head | C29: Pile head | D29: The top of a pile as installed. | E29: string | G29: DIGGS
A30: =IF(ISNA(VLOOKUP(B30,AssociatedElements!B$2:B2940,1,FALSE)),"Not used","") | B30: cutoff_level | C30: Cut-off level | D30: The level to which a pile or column is trimmed, as designed or as constructed. | E30: string | G30: DIGGS
A31: =IF(ISNA(VLOOKUP(B31,AssociatedElements!B$2:B2940,1,FALSE)),"Not used","") | B31: pile_toe | C31: Pile toe | D31: The bottom (tip) of a pile. | E31: string | G31: DIGGS
A32: =IF(ISNA(VLOOKUP(B32,AssociatedElements!B$2:B2940,1,FALSE)),"Not used","") | B32: top_of_inclusion | C32: Top of inclusion | D32: The top of a rigid inclusion or ground improvement column. | E32: string | G32: DIGGS
A33: =IF(ISNA(VLOOKUP(B33,AssociatedElements!B$2:B2940,1,FALSE)),"Not used","") | B33: bottom_of_inclusion | C33: Bottom of inclusion | D33: The bottom of a rigid inclusion or ground improvement column. | E33: string | G33: DIGGS
A34: =IF(ISNA(VLOOKUP(B34,AssociatedElements!B$2:B2940,1,FALSE)),"Not used","") | B34: top_of_rock | C34: Top of rock | D34: The top of rock in the hole, from which a rock socket or rock coring length is measured. | E34: string | G34: DIGGS
A35: =IF(ISNA(VLOOKUP(B35,AssociatedElements!B$2:B2940,1,FALSE)),"Not used","") | B35: line_start | C35: Line start | D35: The first point of a survey line or other linear feature. | E35: string | G35: DIGGS
A36: =IF(ISNA(VLOOKUP(B36,AssociatedElements!B$2:B2940,1,FALSE)),"Not used","") | B36: line_end | C36: Line end | D36: The last point of a survey line or other linear feature. | E36: string | G36: DIGGS
A37: =IF(ISNA(VLOOKUP(B37,AssociatedElements!B$2:B2940,1,FALSE)),"Not used","") | B37: intersection | C37: Intersection | D37: The crossing of this linear feature with another line or feature. | E37: string | G37: DIGGS
A38: =IF(ISNA(VLOOKUP(B38,AssociatedElements!B$2:B2940,1,FALSE)),"Not used","") | B38: benchmark | C38: Benchmark | D38: A monumented point of known elevation. | E38: string | G38: DIGGS
A39: =IF(ISNA(VLOOKUP(B39,AssociatedElements!B$2:B2940,1,FALSE)),"Not used","") | B39: mean_sea_level | C39: Mean sea level | D39: Mean sea level. | E39: string | G39: DIGGS
A40: =IF(ISNA(VLOOKUP(B40,AssociatedElements!B$2:B2940,1,FALSE)),"Not used","") | B40: lowest_astronomical_tide | C40: Lowest astronomical tide | D40: The lowest tide level that can be predicted under average meteorological conditions. | E40: string | G40: DIGGS
...

Sheet AssociatedElements
A1: Start | B1: ID | C1: SourceElement | D1: ConditionalElement
A2: =IF(ISNA(VLOOKUP(B2,Definitions!B$2:B2940,1,FALSE)),"Not used","") | B2: ground_surface | C2: //diggs:Referent/diggs:name
A3: =IF(ISNA(VLOOKUP(B3,Definitions!B$2:B2940,1,FALSE)),"Not used","") | B3: original_ground_surface | C3: //diggs:Referent/diggs:name
A4: =IF(ISNA(VLOOKUP(B4,Definitions!B$2:B2940,1,FALSE)),"Not used","") | B4: finished_grade | C4: //diggs:Referent/diggs:name
A5: =IF(ISNA(VLOOKUP(B5,Definitions!B$2:B2940,1,FALSE)),"Not used","") | B5: working_platform | C5: //diggs:Referent/diggs:name
A6: =IF(ISNA(VLOOKUP(B6,Definitions!B$2:B2940,1,FALSE)),"Not used","") | B6: top_of_load_transfer_platform | C6: //diggs:Referent/diggs:name
A7: =IF(ISNA(VLOOKUP(B7,Definitions!B$2:B2940,1,FALSE)),"Not used","") | B7: bottom_of_excavation | C7: //diggs:Referent/diggs:name
A8: =IF(ISNA(VLOOKUP(B8,Definitions!B$2:B2940,1,FALSE)),"Not used","") | B8: water_surface | C8: //diggs:Referent/diggs:name
A9: =IF(ISNA(VLOOKUP(B9,Definitions!B$2:B2940,1,FALSE)),"Not used","") | B9: sea_floor | C9: //diggs:Referent/diggs:name
A10: =IF(ISNA(VLOOKUP(B10,Definitions!B$2:B2940,1,FALSE)),"Not used","") | B10: mudline | C10: //diggs:Referent/diggs:name
A11: =IF(ISNA(VLOOKUP(B11,Definitions!B$2:B2940,1,FALSE)),"Not used","") | B11: kelly_bushing | C11: //diggs:Referent/diggs:name
A12: =IF(ISNA(VLOOKUP(B12,Definitions!B$2:B2940,1,FALSE)),"Not used","") | B12: rotary_bushing | C12: //diggs:Referent/diggs:name
A13: =IF(ISNA(VLOOKUP(B13,Definitions!B$2:B2940,1,FALSE)),"Not used","") | B13: rotary_table | C13: //diggs:Referent/diggs:name
A14: =IF(ISNA(VLOOKUP(B14,Definitions!B$2:B2940,1,FALSE)),"Not used","") | B14: derrick_floor | C14: //diggs:Referent/diggs:name
A15: =IF(ISNA(VLOOKUP(B15,Definitions!B$2:B2940,1,FALSE)),"Not used","") | B15: crown_valve | C15: //diggs:Referent/diggs:name
A16: =IF(ISNA(VLOOKUP(B16,Definitions!B$2:B2940,1,FALSE)),"Not used","") | B16: casing_flange | C16: //diggs:Referent/diggs:name
A17: =IF(ISNA(VLOOKUP(B17,Definitions!B$2:B2940,1,FALSE)),"Not used","") | B17: top_of_hole | C17: //diggs:Referent/diggs:name
A18: =IF(ISNA(VLOOKUP(B18,Definitions!B$2:B2940,1,FALSE)),"Not used","") | B18: bottom_of_hole | C18: //diggs:Referent/diggs:name
A19: =IF(ISNA(VLOOKUP(B19,Definitions!B$2:B2940,1,FALSE)),"Not used","") | B19: top_of_casing | C19: //diggs:Referent/diggs:name
A20: =IF(ISNA(VLOOKUP(B20,Definitions!B$2:B2940,1,FALSE)),"Not used","") | B20: bottom_of_casing | C20: //diggs:Referent/diggs:name
A21: =IF(ISNA(VLOOKUP(B21,Definitions!B$2:B2940,1,FALSE)),"Not used","") | B21: top_of_riser | C21: //diggs:Referent/diggs:name
A22: =IF(ISNA(VLOOKUP(B22,Definitions!B$2:B2940,1,FALSE)),"Not used","") | B22: top_of_protective_casing | C22: //diggs:Referent/diggs:name
A23: =IF(ISNA(VLOOKUP(B23,Definitions!B$2:B2940,1,FALSE)),"Not used","") | B23: measuring_point | C23: //diggs:Referent/diggs:name
A24: =IF(ISNA(VLOOKUP(B24,Definitions!B$2:B2940,1,FALSE)),"Not used","") | B24: kickoff_point | C24: //diggs:Referent/diggs:name
A25: =IF(ISNA(VLOOKUP(B25,Definitions!B$2:B2940,1,FALSE)),"Not used","") | B25: top_of_core | C25: //diggs:Referent/diggs:name
A26: =IF(ISNA(VLOOKUP(B26,Definitions!B$2:B2940,1,FALSE)),"Not used","") | B26: bottom_of_core | C26: //diggs:Referent/diggs:name
A27: =IF(ISNA(VLOOKUP(B27,Definitions!B$2:B2940,1,FALSE)),"Not used","") | B27: top_of_sample | C27: //diggs:Referent/diggs:name
A28: =IF(ISNA(VLOOKUP(B28,Definitions!B$2:B2940,1,FALSE)),"Not used","") | B28: bottom_of_sample | C28: //diggs:Referent/diggs:name
A29: =IF(ISNA(VLOOKUP(B29,Definitions!B$2:B2940,1,FALSE)),"Not used","") | B29: pile_head | C29: //diggs:Referent/diggs:name
A30: =IF(ISNA(VLOOKUP(B30,Definitions!B$2:B2940,1,FALSE)),"Not used","") | B30: cutoff_level | C30: //diggs:Referent/diggs:name
A31: =IF(ISNA(VLOOKUP(B31,Definitions!B$2:B2940,1,FALSE)),"Not used","") | B31: pile_toe | C31: //diggs:Referent/diggs:name
A32: =IF(ISNA(VLOOKUP(B32,Definitions!B$2:B2940,1,FALSE)),"Not used","") | B32: top_of_inclusion | C32: //diggs:Referent/diggs:name
A33: =IF(ISNA(VLOOKUP(B33,Definitions!B$2:B2940,1,FALSE)),"Not used","") | B33: bottom_of_inclusion | C33: //diggs:Referent/diggs:name
A34: =IF(ISNA(VLOOKUP(B34,Definitions!B$2:B2940,1,FALSE)),"Not used","") | B34: top_of_rock | C34: //diggs:Referent/diggs:name
A35: =IF(ISNA(VLOOKUP(B35,Definitions!B$2:B2940,1,FALSE)),"Not used","") | B35: line_start | C35: //diggs:Referent/diggs:name
A36: =IF(ISNA(VLOOKUP(B36,Definitions!B$2:B2940,1,FALSE)),"Not used","") | B36: line_end | C36: //diggs:Referent/diggs:name
A37: =IF(ISNA(VLOOKUP(B37,Definitions!B$2:B2940,1,FALSE)),"Not used","") | B37: intersection | C37: //diggs:Referent/diggs:name
A38: =IF(ISNA(VLOOKUP(B38,Definitions!B$2:B2940,1,FALSE)),"Not used","") | B38: benchmark | C38: //diggs:Referent/diggs:name
A39: =IF(ISNA(VLOOKUP(B39,Definitions!B$2:B2940,1,FALSE)),"Not used","") | B39: mean_sea_level | C39: //diggs:Referent/diggs:name
A40: =IF(ISNA(VLOOKUP(B40,Definitions!B$2:B2940,1,FALSE)),"Not used","") | B40: lowest_astronomical_tide | C40: //diggs:Referent/diggs:name
...

Sheet AlternateNames
A1: Start | B1: ID | C1: Name | D1: codeSpace
A2: =IF(ISNA(VLOOKUP(B2,Definitions!B$2:B$1839,1,FALSE)),"Not listed","") | B2: ground_surface | C2: GS
A3: =IF(ISNA(VLOOKUP(B3,Definitions!B$2:B$1839,1,FALSE)),"Not listed","") | B3: ground_surface | C3: GL
A4: =IF(ISNA(VLOOKUP(B4,Definitions!B$2:B$1839,1,FALSE)),"Not listed","") | B4: ground_surface | C4: Ground level
A5: =IF(ISNA(VLOOKUP(B5,Definitions!B$2:B$1839,1,FALSE)),"Not listed","") | B5: ground_surface | C5: Existing grade
A6: =IF(ISNA(VLOOKUP(B6,Definitions!B$2:B$1839,1,FALSE)),"Not listed","") | B6: original_ground_surface | C6: OGS
A7: =IF(ISNA(VLOOKUP(B7,Definitions!B$2:B$1839,1,FALSE)),"Not listed","") | B7: original_ground_surface | C7: OGL
A8: =IF(ISNA(VLOOKUP(B8,Definitions!B$2:B$1839,1,FALSE)),"Not listed","") | B8: original_ground_surface | C8: Original ground level
A9: =IF(ISNA(VLOOKUP(B9,Definitions!B$2:B$1839,1,FALSE)),"Not listed","") | B9: original_ground_surface | C9: Natural ground
A10: =IF(ISNA(VLOOKUP(B10,Definitions!B$2:B$1839,1,FALSE)),"Not listed","") | B10: finished_grade | C10: FG
A11: =IF(ISNA(VLOOKUP(B11,Definitions!B$2:B$1839,1,FALSE)),"Not listed","") | B11: finished_grade | C11: FGL
A12: =IF(ISNA(VLOOKUP(B12,Definitions!B$2:B$1839,1,FALSE)),"Not listed","") | B12: finished_grade | C12: Finished ground level
A13: =IF(ISNA(VLOOKUP(B13,Definitions!B$2:B$1839,1,FALSE)),"Not listed","") | B13: working_platform | C13: WP
... A83: =IF(ISNA(VLOOKUP(B83,Definitions!B$2:B$1839,1,FALSE)),"Not listed","") | B83: chart_datum | C83: CD

Sheet ValueBindings
A1: Start | B1: ID | C1: SubjectElement | D1: Method | E1: RealizedValueXpath | F1: ReferenceValueXpath | G1: ReferenceSource | H1: ReferenceEvaluation | I1: NormalizeByXpath
A2: =IF(ISNA(VLOOKUP(B2,Definitions!B$2:B$1839,1,FALSE)),"Not listed","")
A3: =IF(ISNA(VLOOKUP(B3,Definitions!B$2:B$1839,1,FALSE)),"Not listed","")
A4: =IF(ISNA(VLOOKUP(B4,Definitions!B$2:B$1839,1,FALSE)),"Not listed","")
A5: =IF(ISNA(VLOOKUP(B5,Definitions!B$2:B$1839,1,FALSE)),"Not listed","")
A6: =IF(ISNA(VLOOKUP(B6,Definitions!B$2:B$1839,1,FALSE)),"Not listed","")
A7: =IF(ISNA(VLOOKUP(B7,Definitions!B$2:B$1839,1,FALSE)),"Not listed","")
A8: =IF(ISNA(VLOOKUP(B8,Definitions!B$2:B$1839,1,FALSE)),"Not listed","")
A9: =IF(ISNA(VLOOKUP(B9,Definitions!B$2:B$1839,1,FALSE)),"Not listed","")
A10: =IF(ISNA(VLOOKUP(B10,Definitions!B$2:B$1839,1,FALSE)),"Not listed","")
A11: =IF(ISNA(VLOOKUP(B11,Definitions!B$2:B$1839,1,FALSE)),"Not listed","")
A12: =IF(ISNA(VLOOKUP(B12,Definitions!B$2:B$1839,1,FALSE)),"Not listed","")
A13: =IF(ISNA(VLOOKUP(B13,Definitions!B$2:B$1839,1,FALSE)),"Not listed","")
... A31: =IF(ISNA(VLOOKUP(B31,Definitions!B$2:B$1839,1,FALSE)),"Not listed","")

Sheet Lists
A1: DataType | B1: DataType2 | C1: QuantityClass | D1: Column2 | E1: Column3
B2: anyURI | C2: absorbed dose
B3: base64binary | C3: activity [of radioactivity]
B4: boolean | C4: amount of substance
B5: byte | C5: amount of substance per amount of substance
B6: date | C6: amount of substance per area
B7: dateTime | C7: amount of substance per mass | D7: use for cation exchange capacity | E7: not yet used nor in EML Dictionary
B8: decimal | C8: amount of substance per time
B9: double | C9: (amount of substance per time) per area
B10: duration | C10: amount of substance per volume
B11: float | C11: angle per length
B12: gDay | C12: angle per volume
B13: gMonth | C13: angular acceleration
B14: gMonthDay | C14: angular velocity
B15: gYear | C15: api gamma ray
B16: gYearMonth | C16: api gravity
B17: hexBinary | C17: api neutron
B18: integer | C18: area
B19: language | C19: area per amount of substance
B20: long | C20: area per area
B21: negativeInteger | C21: area per count | D21: In EML schema but not in EML dictionary
B22: nonNegativeInteger | C22: area per mass
B23: nonPositiveInteger | C23: area per time
B24: normalizedString | C24: area per volume
B25: positiveInteger | C25: attenuation per frequency interval
B26: short | C26: capacitance
B27: string | C27: data transfer speed
B28: string | C28: diffusion coefficient
B29: time | C29: diffusive time of flight | D29: In EML schema but not in EML dictionary
B30: token | C30: digital storage
B31: unsignedByte | C31: dimensionless
B32: unsignedInt | C32: dipole moment
B33: unsignedLong | C33: dose equivalent
B34: unsignedShort | C34: dynamic viscosity
B35: vector | C35: electric charge
C36: electric charge per area
C37: electric charge per mass
C38: electric charge per volume
C39: electric conductance
C40: electric conductivity
...
