Workbook

Sheet DictionaryName
A1: Start | B1: Dictionary ID | C1: DictionaryFile | D1: DictionaryName | E1: Description
E2: Leave this line blank
B3: type | C3: sampleType | D3: DIGGS Sample Type | E3: Controlled vocabulary for diggs:SampleType/type, describing sample form only - the physical means by which a material sample was obtained (tube, drive, core, bulk, block, or fluid/gas extraction technique). Deliberately excludes sample class, sampler brand, insertion method, condition and purpose, each already modeled as its own diggs:Sample property (classification, samplerInsertionMethod, condition, purpose) or, for proprietary sampler brands, as an AlternateNames synonym on the relevant term here rather than a first-class code. Anchored on ISO 22475-1:2021 and the AGS4.2 SAMP_TYPE vocabulary rather than ASTM designations, since ASTM's sampling-practice family (D1587, D3550, D2113, D4220) has been withdrawn wholesale with no ASTM replacement named; an ASTM designation is cited as a secondary anchor only where one still stands. Not bound to diggs:DesignSampleType - that type deliberately has no type-equivalent property (see its own documentation in core/Core.xsd), so this vocabulary serves the as-built diggs:Sample object only.

Sheet Definitions
A1: Start | B1: ID | C1: Name | D1: Description | E1: DataType | F1: QuantityClass | G1: Authority | H1: Reference
A2: =IF(ISNA(VLOOKUP(B2,AssociatedElements!B$2:B2940,1,FALSE)),"Not used","") | B2: open_tube | C2: Open-tube (open-drive) sample | D2: Thin- or thick-walled tube sample recovered by static or dynamic push without a separating piston. | E2: string | G2: ISO 22475-1 | H2: https://www.iso.org/standard/71002.html
A3: =IF(ISNA(VLOOKUP(B3,AssociatedElements!B$2:B2941,1,FALSE)),"Not used","") | B3: thin_walled_tube | C3: Thin-walled (Shelby) tube sample | D3: Open-tube sample using a thin-walled tube meeting ISO 22475-1's edge-taper, area-ratio and inside-clearance-ratio criteria for minimal soil disturbance. | E3: string | G3: ASTM D1587/D1587M | H3: https://store.astm.org/d1587_d1587m-15.html
A4: =IF(ISNA(VLOOKUP(B4,AssociatedElements!B$2:B2942,1,FALSE)),"Not used","") | B4: piston | C4: Stationary-piston tube sample | D4: Thin-walled tube sample taken with an internal piston held stationary at the sampling depth to reduce disturbance and improve recovery in soft or sensitive soils. | E4: string | G4: ASTM D6519/D6519M | H4: https://store.astm.org/d6519_d6519m-23.html
A5: =IF(ISNA(VLOOKUP(B5,AssociatedElements!B$2:B2943,1,FALSE)),"Not used","") | B5: split_barrel | C5: Split-barrel (split-spoon) drive sample | D5: Disturbed sample recovered in a longitudinally split, driven barrel sampler, most commonly as part of the Standard Penetration Test. | E5: string | G5: ASTM D1586/D1586M | H5: https://www.astm.org/standards/d1586
A6: =IF(ISNA(VLOOKUP(B6,AssociatedElements!B$2:B2944,1,FALSE)),"Not used","") | B6: split_barrel_liner | C6: Split-barrel sample retained in liner | D6: Split-barrel drive sample retained in a removable liner rather than extruded directly from the barrel. | E6: string | G6: ASTM D1586/D1586M | H6: https://www.astm.org/standards/d1586
A7: =IF(ISNA(VLOOKUP(B7,AssociatedElements!B$2:B2945,1,FALSE)),"Not used","") | B7: ring_lined_barrel | C7: Thick-wall ring-lined (California) sample | D7: Sample recovered in a thick-walled, driven barrel fitted with stacked internal retaining rings. | E7: string | G7: ASTM D3550/D3550M | H7: https://store.astm.org/d3550_d3550m-17.html
A8: =IF(ISNA(VLOOKUP(B8,AssociatedElements!B$2:B2946,1,FALSE)),"Not used","") | B8: window | C8: Window-sampler sample | D8: Sample recovered in the open mode (without liner) from a windowed sampler advanced by percussive or vibratory driving, typical of UK/European light cable-percussion practice. | E8: string | G8: ISO 22475-1 | H8: https://www.iso.org/standard/71002.html
A9: =IF(ISNA(VLOOKUP(B9,AssociatedElements!B$2:B2947,1,FALSE)),"Not used","") | B9: windowless | C9: Windowless (dynamic liner) sample | D9: Sample recovered in a lined tube advanced by static or dynamic driving, without an open viewing window in the barrel wall. | E9: string | G9: ISO 22475-1 | H9: https://www.iso.org/standard/71002.html
A10: =IF(ISNA(VLOOKUP(B10,AssociatedElements!B$2:B2948,1,FALSE)),"Not used","") | B10: triple_tube_soil | C10: Triple-tube soil core (Mazier-type) | D10: Continuous soil core recovered with a triple-tube core barrel, minimizing rotational disturbance to the retained liner. | E10: string | G10: DIGGS
A11: =IF(ISNA(VLOOKUP(B11,AssociatedElements!B$2:B2949,1,FALSE)),"Not used","") | B11: bulk | C11: Bulk disturbed sample | D11: General disturbed sample of unspecified sampler or method, collected to represent the material at a location without preserving structure. | E11: string | G11: DIGGS
A12: =IF(ISNA(VLOOKUP(B12,AssociatedElements!B$2:B2950,1,FALSE)),"Not used","") | B12: large_bulk | C12: Large bulk sample, earthworks testing | D12: Large-volume disturbed sample collected for earthworks or compaction-family testing requiring more material than a standard bulk sample. | E12: string | G12: DIGGS
A13: =IF(ISNA(VLOOKUP(B13,AssociatedElements!B$2:B2951,1,FALSE)),"Not used","") | B13: small_disturbed | C13: Small disturbed (jar/bag) sample | D13: Small disturbed sample retained in a jar or bag, typically for moisture content or visual classification only. | E13: string | G13: DIGGS
A14: =IF(ISNA(VLOOKUP(B14,AssociatedElements!B$2:B2952,1,FALSE)),"Not used","") | B14: grab | C14: Grab sample (bucket, spoil, stockpile) | D14: Sample taken by hand or bucket from spoil, cuttings, or a stockpile rather than from an undisturbed in-situ location. | E14: string | G14: ISO 22475-1 | H14: https://www.iso.org/standard/71002.html
A15: =IF(ISNA(VLOOKUP(B15,AssociatedElements!B$2:B2953,1,FALSE)),"Not used","") | B15: cuttings | C15: Drill cuttings / returns | D15: Material returned to the surface by the drilling process itself (flush return or auger flights) rather than by a dedicated sampler. | E15: string | G15: ISO 22475-1 | H15: https://www.iso.org/standard/71002.html
A16: =IF(ISNA(VLOOKUP(B16,AssociatedElements!B$2:B2954,1,FALSE)),"Not used","") | B16: block | C16: Block sample, hand-cut (cubical or cylindrical) | D16: Sample hand-cut from an excavation, trial pit, or natural exposure, preserving orientation and structure; typically the highest achievable quality class. | E16: string | G16: ASTM D7015/D7015M | H16: https://store.astm.org/d7015_d7015m-18.html
A17: =IF(ISNA(VLOOKUP(B17,AssociatedElements!B$2:B2955,1,FALSE)),"Not used","") | B17: rotary_core | C17: Rotary core (single/double/triple tube) | D17: Rock or cohesive-soil core recovered by rotary drilling with a single-, double-, or triple-tube core barrel. | E17: string | G17: ASTM D2113 | H17: https://www.astm.org/standards/d2113
A18: =IF(ISNA(VLOOKUP(B18,AssociatedElements!B$2:B2956,1,FALSE)),"Not used","") | B18: wireline_core | C18: Wireline core | D18: Rotary core recovered through the drill string via a retrievable inner tube, without withdrawing the full drill string. | E18: string | G18: ISO 22475-1 | H18: https://www.iso.org/standard/71002.html
A19: =IF(ISNA(VLOOKUP(B19,AssociatedElements!B$2:B2957,1,FALSE)),"Not used","") | B19: dry_core | C19: Rotary dry core | D19: Rotary core recovered without circulating fluid or air flush. | E19: string | G19: ISO 22475-1 | H19: https://www.iso.org/standard/71002.html
A20: =IF(ISNA(VLOOKUP(B20,AssociatedElements!B$2:B2958,1,FALSE)),"Not used","") | B20: gravity_core | C20: Gravity core | D20: Marine or lacustrine sediment core recovered by free-fall penetration of a weighted corer. | E20: string | G20: DIGGS
A21: =IF(ISNA(VLOOKUP(B21,AssociatedElements!B$2:B2959,1,FALSE)),"Not used","") | B21: vibrocore | C21: Vibrocore | D21: Marine or lacustrine sediment core recovered using a vibrating corer to advance the tube. | E21: string | G21: DIGGS
A22: =IF(ISNA(VLOOKUP(B22,AssociatedElements!B$2:B2960,1,FALSE)),"Not used","") | B22: piston_core | C22: Marine piston core | D22: Marine sediment core recovered with a piston corer, using an internal piston to improve recovery and reduce disturbance at depth. | E22: string | G22: DIGGS
A23: =IF(ISNA(VLOOKUP(B23,AssociatedElements!B$2:B2961,1,FALSE)),"Not used","") | B23: pumped | C23: Pumped water sample | D23: Groundwater sample extracted by pumping. | E23: string | G23: ISO 22475-1 | H23: https://www.iso.org/standard/71002.html
A24: =IF(ISNA(VLOOKUP(B24,AssociatedElements!B$2:B2962,1,FALSE)),"Not used","") | B24: discrete_sampler | C24: Discrete-depth water sampler / bailer | D24: Groundwater sample extracted from a specific depth using a discrete-interval sampler or bailer. | E24: string | G24: ISO 22475-1 | H24: https://www.iso.org/standard/71002.html
A25: =IF(ISNA(VLOOKUP(B25,AssociatedElements!B$2:B2963,1,FALSE)),"Not used","") | B25: vacuum_bottle | C25: Vacuum-bottle water sample | D25: Groundwater sample extracted using a pre-evacuated vacuum bottle. | E25: string | G25: ISO 22475-1 | H25: https://www.iso.org/standard/71002.html
A26: =IF(ISNA(VLOOKUP(B26,AssociatedElements!B$2:B2964,1,FALSE)),"Not used","") | B26: water_sample | C26: Water sample, extraction method not recorded | D26: Groundwater or surface-water sample whose specific extraction technique (pumped, discrete sampler, or vacuum bottle) was not recorded; use one of the more specific water terms when the technique is known. Matches AGS4.2 codes W and EW, which do not distinguish extraction form. | E26: string | G26: DIGGS
A27: =IF(ISNA(VLOOKUP(B27,AssociatedElements!B$2:B2965,1,FALSE)),"Not used","") | B27: soil_gas_active | C27: Active (pumped) soil-gas sample | D27: Soil-gas or vapor sample extracted by pumping a volume of gas from the vadose zone into a collection device. | E27: string | G27: ASTM D7663 | H27: https://store.astm.org/d7663-12r18e01.html
A28: =IF(ISNA(VLOOKUP(B28,AssociatedElements!B$2:B2966,1,FALSE)),"Not used","") | B28: soil_gas_passive | C28: Passive (sorbent) soil-gas sample | D28: Soil-gas or vapor sample collected by leaving a sorbent material in the ground to adsorb vapors over an exposure period. | E28: string | G28: ASTM D7758 | H28: https://store.astm.org/d7758-17.html
A29: =IF(ISNA(VLOOKUP(B29,AssociatedElements!B$2:B2967,1,FALSE)),"Not used","") | B29: gas_sample | C29: Gas/vapour sample, extraction method not recorded | D29: Gas or vapor sample whose specific extraction technique (active/pumped or passive/sorbent) was not recorded; use one of the more specific soil-gas terms when the technique is known. Matches AGS4.2 codes G and EV, which do not distinguish extraction form. | E29: string | G29: DIGGS
A30: =IF(ISNA(VLOOKUP(B30,AssociatedElements!B$2:B2968,1,FALSE)),"Not used","") | B30: fresh_batch | C30: Sample of fresh, unset concrete or grout | D30: Sample taken from a fresh, unset batch of concrete, grout, or similar cementitious material prior to placement or curing. | E30: string | G30: DIGGS
A31: =IF(ISNA(VLOOKUP(B31,AssociatedElements!B$2:B2969,1,FALSE)),"Not used","") | B31: cast_cube | C31: Cube cast in a mould | D31: Concrete or grout specimen cast to a cubical mould for curing and subsequent strength testing. | E31: string | G31: DIGGS
A32: =IF(ISNA(VLOOKUP(B32,AssociatedElements!B$2:B2970,1,FALSE)),"Not used","") | B32: cast_cylinder | C32: Cylinder cast in a mould | D32: Concrete or grout specimen cast to a cylindrical mould for curing and subsequent strength testing. | E32: string | G32: DIGGS
A33: =IF(ISNA(VLOOKUP(B33,AssociatedElements!B$2:B2971,1,FALSE)),"Not used","") | B33: hardened_core | C33: Core cut from hardened concrete or grout | D33: Core drilled from hardened, in-place concrete or grout. | E33: string | G33: DIGGS
A34: =IF(ISNA(VLOOKUP(B34,AssociatedElements!B$2:B2972,1,FALSE)),"Not used","")
A35: =IF(ISNA(VLOOKUP(B35,AssociatedElements!B$2:B2973,1,FALSE)),"Not used","")
A36: =IF(ISNA(VLOOKUP(B36,AssociatedElements!B$2:B2974,1,FALSE)),"Not used","")
A37: =IF(ISNA(VLOOKUP(B37,AssociatedElements!B$2:B2975,1,FALSE)),"Not used","")

Sheet AssociatedElements
A1: Start | B1: ID | C1: SourceElement | D1: ConditionalElement
A2: =IF(ISNA(VLOOKUP(#REF!,Definitions!B$2:B$1839,1,FALSE)),"Not listed","") | B2: open_tube | C2: //diggs:Sample/diggs:type
A3: =IF(ISNA(VLOOKUP(B3,Definitions!B$2:B$1839,1,FALSE)),"Not listed","") | B3: thin_walled_tube | C3: //diggs:Sample/diggs:type
A4: =IF(ISNA(VLOOKUP(B4,Definitions!B$2:B$1839,1,FALSE)),"Not listed","") | B4: piston | C4: //diggs:Sample/diggs:type
A5: =IF(ISNA(VLOOKUP(B5,Definitions!B$2:B$1839,1,FALSE)),"Not listed","") | B5: split_barrel | C5: //diggs:Sample/diggs:type
A6: =IF(ISNA(VLOOKUP(B6,Definitions!B$2:B$1839,1,FALSE)),"Not listed","") | B6: split_barrel_liner | C6: //diggs:Sample/diggs:type
A7: =IF(ISNA(VLOOKUP(B7,Definitions!B$2:B$1839,1,FALSE)),"Not listed","") | B7: ring_lined_barrel | C7: //diggs:Sample/diggs:type
A8: =IF(ISNA(VLOOKUP(B8,Definitions!B$2:B$1839,1,FALSE)),"Not listed","") | B8: window | C8: //diggs:Sample/diggs:type
A9: =IF(ISNA(VLOOKUP(B9,Definitions!B$2:B$1839,1,FALSE)),"Not listed","") | B9: windowless | C9: //diggs:Sample/diggs:type
A10: =IF(ISNA(VLOOKUP(B10,Definitions!B$2:B$1839,1,FALSE)),"Not listed","") | B10: triple_tube_soil | C10: //diggs:Sample/diggs:type
A11: =IF(ISNA(VLOOKUP(B11,Definitions!B$2:B$1839,1,FALSE)),"Not listed","") | B11: bulk | C11: //diggs:Sample/diggs:type
A12: =IF(ISNA(VLOOKUP(B12,Definitions!B$2:B$1839,1,FALSE)),"Not listed","") | B12: large_bulk | C12: //diggs:Sample/diggs:type
A13: =IF(ISNA(VLOOKUP(B13,Definitions!B$2:B$1839,1,FALSE)),"Not listed","") | B13: small_disturbed | C13: //diggs:Sample/diggs:type
A14: =IF(ISNA(VLOOKUP(B14,Definitions!B$2:B$1839,1,FALSE)),"Not listed","") | B14: grab | C14: //diggs:Sample/diggs:type
... A33: =IF(ISNA(VLOOKUP(B33,Definitions!B$2:B$1839,1,FALSE)),"Not listed","") | B33: hardened_core | C33: //diggs:Sample/diggs:type
A34: =IF(ISNA(VLOOKUP(B34,Definitions!B$2:B$1839,1,FALSE)),"Not listed","")
A35: =IF(ISNA(VLOOKUP(B35,Definitions!B$2:B$1839,1,FALSE)),"Not listed","")
A36: =IF(ISNA(VLOOKUP(B36,Definitions!B$2:B$1839,1,FALSE)),"Not listed","")
A37: =IF(ISNA(VLOOKUP(B37,Definitions!B$2:B$1839,1,FALSE)),"Not listed","")

Sheet AlternateNames
A1: Start | B1: ID | C1: Name | D1: codeSpace
A2: =IF(ISNA(VLOOKUP(B2,Definitions!B$2:B$1839,1,FALSE)),"Not listed","") | B2: LFS | C2: An alternate name for the definition code given in ID | D2: A URI to provide context for the name. Typically this might identify an authority, a language. a dictionary, or some other metadata value
B3: triple_tube_soil | C3: Mazier sampler
B4: triple_tube_soil | C4: Mostap sampler
B5: piston_core | C5: STACORE sampler

Sheet Lists
A1: DataType | B1: DataType2 | C1: QuantityClass | D1: Column2 | E1: Column3
B2: anyURI | C2: absorbed dose
B3: base64binary | C3: activity [of radioactivity]
B4: boolean | C4: amount of substance
B5: byte | C5: amount of substance per amount of substance
B6: date | C6: amount of substance per area
B7: dateTime | C7: amount of substance per mass | D7: use for cation exchange capacity | E7: not yet used nor in EML Dictionary
B8: decimal | C8: amount of substance per time
B9: double | C9: (amount of substance per time) per area
B10: duration | C10: amount of substance per volume
B11: float | C11: angle per length
B12: gDay | C12: angle per volume
B13: gMonth | C13: angular acceleration
B14: gMonthDay | C14: angular velocity
B15: gYear | C15: api gamma ray
B16: gYearMonth | C16: api gravity
B17: hexBinary | C17: api neutron
B18: integer | C18: area
B19: language | C19: area per amount of substance
B20: long | C20: area per area
B21: negativeInteger | C21: area per count | D21: In EML schema but not in EML dictionary
B22: nonNegativeInteger | C22: area per mass
B23: nonPositiveInteger | C23: area per time
B24: normalizedString | C24: area per volume
B25: positiveInteger | C25: attenuation per frequency interval
B26: short | C26: capacitance
B27: string | C27: data transfer speed
B28: string | C28: diffusion coefficient
B29: time | C29: diffusive time of flight | D29: In EML schema but not in EML dictionary
B30: token | C30: digital storage
B31: unsignedByte | C31: dimensionless
B32: unsignedInt | C32: dipole moment
B33: unsignedLong | C33: dose equivalent
B34: unsignedShort | C34: dynamic viscosity
B35: vector | C35: electric charge
C36: electric charge per area
C37: electric charge per mass
C38: electric charge per volume
C39: electric conductance
C40: electric conductivity
...
