Workbook

Sheet DictionaryName
A1: Start | B1: Dictionary ID | C1: DictionaryFile | D1: DictionaryName | E1: Description
E2: Leave this line blank
B3: specimenOrigin | C3: specimenOrigin | D3: DIGGS Specimen Origin Codelist Definitions | E3: Codes classifying how a specimen of manufactured cementitious material was made. Used for the value of diggs:GroutSpecimen/diggs:specimenOrigin.

Sheet Definitions
A1: Start | B1: ID | C1: Name | D1: Description | E1: DataType | F1: QuantityClass | G1: Authority | H1: Reference
A2: =IF(ISNA(VLOOKUP(B2,AssociatedElements!B$2:B2940,1,FALSE)),"Not used","") | B2: molded | C2: Molded | D2: Molded from fresh material in a mold and cured. Source: ASTM C31/C31M, C192/C192M; EN 12390-2; ISO 1920-3. | E2: string | G2: DIGGS | H2: https://diggsml.org/def/registry/DIGGS/0/specifications.xml#astm_c31
A3: =IF(ISNA(VLOOKUP(B3,AssociatedElements!B$2:B2941,1,FALSE)),"Not used","") | B3: cast_in_place | C3: Cast in place | D3: Molded in place in a special mold attached to the formwork, so that the specimen cures within the structure. Source: ASTM C873/C873M. | E3: string | G3: DIGGS | H3: https://diggsml.org/def/registry/DIGGS/0/specifications.xml#astm_c873
A4: =IF(ISNA(VLOOKUP(B4,AssociatedElements!B$2:B2942,1,FALSE)),"Not used","") | B4: cored | C4: Cored | D4: A core drilled from hardened material. Source: ASTM C42/C42M; EN 12504-1; ISO 1920-6; JIS A 1107. | E4: string | G4: DIGGS | H4: https://diggsml.org/def/registry/DIGGS/0/specifications.xml#astm_c42
A5: =IF(ISNA(VLOOKUP(B5,AssociatedElements!B$2:B2943,1,FALSE)),"Not used","") | B5: sawed | C5: Sawed | D5: Sawed from hardened material. Source: ASTM C42/C42M; ISO 1920-4. | E5: string | G5: DIGGS | H5: https://diggsml.org/def/registry/DIGGS/0/specifications.xml#astm_c42
A6: =IF(ISNA(VLOOKUP(B6,AssociatedElements!B$2:B2944,1,FALSE)),"Not used","")
A7: =IF(ISNA(VLOOKUP(B7,AssociatedElements!B$2:B2945,1,FALSE)),"Not used","")
A8: =IF(ISNA(VLOOKUP(B8,AssociatedElements!B$2:B2946,1,FALSE)),"Not used","")
A9: =IF(ISNA(VLOOKUP(B9,AssociatedElements!B$2:B2947,1,FALSE)),"Not used","")
A10: =IF(ISNA(VLOOKUP(B10,AssociatedElements!B$2:B2948,1,FALSE)),"Not used","")
A11: =IF(ISNA(VLOOKUP(B11,AssociatedElements!B$2:B2949,1,FALSE)),"Not used","")
A12: =IF(ISNA(VLOOKUP(B12,AssociatedElements!B$2:B2950,1,FALSE)),"Not used","")
A13: =IF(ISNA(VLOOKUP(B13,AssociatedElements!B$2:B2951,1,FALSE)),"Not used","")
A14: =IF(ISNA(VLOOKUP(B14,AssociatedElements!B$2:B2952,1,FALSE)),"Not used","")
A15: =IF(ISNA(VLOOKUP(B15,AssociatedElements!B$2:B2953,1,FALSE)),"Not used","")
A16: =IF(ISNA(VLOOKUP(B16,AssociatedElements!B$2:B2954,1,FALSE)),"Not used","")
A17: =IF(ISNA(VLOOKUP(B17,AssociatedElements!B$2:B2955,1,FALSE)),"Not used","")
... A37: =IF(ISNA(VLOOKUP(B37,AssociatedElements!B$2:B2975,1,FALSE)),"Not used","")

Sheet AssociatedElements
A1: Start | B1: ID | C1: SourceElement | D1: ConditionalElement
A2: =IF(ISNA(VLOOKUP(#REF!,Definitions!B$2:B$1839,1,FALSE)),"Not listed","") | B2: molded | C2: //diggs:GroutSpecimen/diggs:specimenOrigin
A3: =IF(ISNA(VLOOKUP(B3,Definitions!B$2:B$1839,1,FALSE)),"Not listed","") | B3: cast_in_place | C3: //diggs:GroutSpecimen/diggs:specimenOrigin
A4: =IF(ISNA(VLOOKUP(B4,Definitions!B$2:B$1839,1,FALSE)),"Not listed","") | B4: cored | C4: //diggs:GroutSpecimen/diggs:specimenOrigin
A5: =IF(ISNA(VLOOKUP(B5,Definitions!B$2:B$1839,1,FALSE)),"Not listed","") | B5: sawed | C5: //diggs:GroutSpecimen/diggs:specimenOrigin
A6: =IF(ISNA(VLOOKUP(B6,Definitions!B$2:B$1839,1,FALSE)),"Not listed","")
A7: =IF(ISNA(VLOOKUP(B7,Definitions!B$2:B$1839,1,FALSE)),"Not listed","")
A8: =IF(ISNA(VLOOKUP(B8,Definitions!B$2:B$1839,1,FALSE)),"Not listed","")
A9: =IF(ISNA(VLOOKUP(B9,Definitions!B$2:B$1839,1,FALSE)),"Not listed","")
A10: =IF(ISNA(VLOOKUP(B10,Definitions!B$2:B$1839,1,FALSE)),"Not listed","")
A11: =IF(ISNA(VLOOKUP(B11,Definitions!B$2:B$1839,1,FALSE)),"Not listed","")
A12: =IF(ISNA(VLOOKUP(B12,Definitions!B$2:B$1839,1,FALSE)),"Not listed","")
A13: =IF(ISNA(VLOOKUP(B13,Definitions!B$2:B$1839,1,FALSE)),"Not listed","")
A14: =IF(ISNA(VLOOKUP(B14,Definitions!B$2:B$1839,1,FALSE)),"Not listed","")
A15: =IF(ISNA(VLOOKUP(B15,Definitions!B$2:B$1839,1,FALSE)),"Not listed","")
A16: =IF(ISNA(VLOOKUP(B16,Definitions!B$2:B$1839,1,FALSE)),"Not listed","")
A17: =IF(ISNA(VLOOKUP(B17,Definitions!B$2:B$1839,1,FALSE)),"Not listed","")
... A37: =IF(ISNA(VLOOKUP(B37,Definitions!B$2:B$1839,1,FALSE)),"Not listed","")

Sheet AlternateNames
A1: Start | B1: ID | C1: Name | D1: codeSpace
A2: =IF(ISNA(VLOOKUP(B2,Definitions!B$2:B$1839,1,FALSE)),"Not listed","") | B2: LFS | C2: An alternate name for the definition code given in ID | D2: A URI to provide context for the name. Typically this might identify an authority, a language. a dictionary, or some other metadata value

Sheet ValueBindings
A1: Start | B1: ID | C1: SubjectElement | D1: Method | E1: RealizedValueXpath | F1: ReferenceValueXpath | G1: ReferenceSource | H1: ReferenceEvaluation | I1: NormalizeByXpath
A2: =IF(ISNA(VLOOKUP(B2,Definitions!B$2:B$1839,1,FALSE)),"Not listed","")
A3: =IF(ISNA(VLOOKUP(B3,Definitions!B$2:B$1839,1,FALSE)),"Not listed","")
A4: =IF(ISNA(VLOOKUP(B4,Definitions!B$2:B$1839,1,FALSE)),"Not listed","")
A5: =IF(ISNA(VLOOKUP(B5,Definitions!B$2:B$1839,1,FALSE)),"Not listed","")
A6: =IF(ISNA(VLOOKUP(B6,Definitions!B$2:B$1839,1,FALSE)),"Not listed","")
A7: =IF(ISNA(VLOOKUP(B7,Definitions!B$2:B$1839,1,FALSE)),"Not listed","")
A8: =IF(ISNA(VLOOKUP(B8,Definitions!B$2:B$1839,1,FALSE)),"Not listed","")
A9: =IF(ISNA(VLOOKUP(B9,Definitions!B$2:B$1839,1,FALSE)),"Not listed","")
A10: =IF(ISNA(VLOOKUP(B10,Definitions!B$2:B$1839,1,FALSE)),"Not listed","")
A11: =IF(ISNA(VLOOKUP(B11,Definitions!B$2:B$1839,1,FALSE)),"Not listed","")
A12: =IF(ISNA(VLOOKUP(B12,Definitions!B$2:B$1839,1,FALSE)),"Not listed","")
A13: =IF(ISNA(VLOOKUP(B13,Definitions!B$2:B$1839,1,FALSE)),"Not listed","")
... A31: =IF(ISNA(VLOOKUP(B31,Definitions!B$2:B$1839,1,FALSE)),"Not listed","")

Sheet Lists
A1: DataType | B1: DataType2 | C1: QuantityClass | D1: Column2 | E1: Column3
B2: anyURI | C2: absorbed dose
B3: base64binary | C3: activity [of radioactivity]
B4: boolean | C4: amount of substance
B5: byte | C5: amount of substance per amount of substance
B6: date | C6: amount of substance per area
B7: dateTime | C7: amount of substance per mass | D7: use for cation exchange capacity | E7: not yet used nor in EML Dictionary
B8: decimal | C8: amount of substance per time
B9: double | C9: (amount of substance per time) per area
B10: duration | C10: amount of substance per volume
B11: float | C11: angle per length
B12: gDay | C12: angle per volume
B13: gMonth | C13: angular acceleration
B14: gMonthDay | C14: angular velocity
B15: gYear | C15: api gamma ray
B16: gYearMonth | C16: api gravity
B17: hexBinary | C17: api neutron
B18: integer | C18: area
B19: language | C19: area per amount of substance
B20: long | C20: area per area
B21: negativeInteger | C21: area per count | D21: In EML schema but not in EML dictionary
B22: nonNegativeInteger | C22: area per mass
B23: nonPositiveInteger | C23: area per time
B24: normalizedString | C24: area per volume
B25: positiveInteger | C25: attenuation per frequency interval
B26: short | C26: capacitance
B27: string | C27: data transfer speed
B28: string | C28: diffusion coefficient
B29: time | C29: diffusive time of flight | D29: In EML schema but not in EML dictionary
B30: token | C30: digital storage
B31: unsignedByte | C31: dimensionless
B32: unsignedInt | C32: dipole moment
B33: unsignedLong | C33: dose equivalent
B34: unsignedShort | C34: dynamic viscosity
B35: vector | C35: electric charge
C36: electric charge per area
C37: electric charge per mass
C38: electric charge per volume
C39: electric conductance
C40: electric conductivity
...
